Workbook

Sheet 客户基础数据
A1: 序号 | B1: 客户编号 | C1: 中文名称 | D1: 越南名称 | E1: 英文名称 | F1: 简称 | G1: 税号 | H1: 公司地址(VN) | I1: 公司电话 | J1: Người đại diện theo pháp luật: | K1: 公司法人代表（中文） | L1: Chức vụ: | M1: 代表职位（中文） | N1: 仓库地址 | O1: 仓库联系人 | P1: 联系方式 | Q1: 港口/关口 | R1: 送货时间 | S1: 运输问题 | T1: 财务联系人 | U1: 财务联系方式 | V1: 邮箱 | W1: 客户编号 | X1: 银行 | Y1: 银行 | Z1: 银行账号 | AA1: 海天销售 | AB1: 其他 | AC1: 快递 | AD1: 中文翻译地址 | AE1: 备注 | AF1: 经销商协议付款条款
A2: 1 | B2: 2141010050 | C2: 越南俊芳进出口销售贸易公司 | D2: CÔNG TY TNHH THƯƠNG MẠI XUẤT NHẬP KHẨU TUẤN PHƯƠNG | E2: CONG TY TNHH THUONG MAI XUAT NHAP KHAU TUAN PHUONG | F2: 俊芳 | G2: 0108272471 | H2: Số 77 Phố Hàm Tử Quan, Phường Phúc Tân, Quận Hoàn Kiếm, Thành phố Hà Nội, Việt Nam | I2: 984968999 | J2: Bùi Tuyết Chinh | K2: Bui Tuyet Chinh | L2: GIÁM ĐỐC | M2: 经理 | N2: Khu khả lễ.phường võ cường. Thành phố bắc ninh | O2: Anh Thành Tuấn Phương | P2: 098 4968999 | Q2: CHI MA, LANG SON，VIETNAM/HAIPHONG ,VIETNAM | R2: 每天晚上10点 | W2: =B2 -> 2141010050 | X2: Ngân hàng TMCP Kỹ thương Việt Nam（Techcombank ) | Y2: 越南科技商业股份银行（Techcombank ) | Z2: 1903720864017 | AA2: 郑明黄 | AC2: 098 4968999， a Thành ，1138 nguyễn khoái. Lĩnh nam. Hoàng mai. | AD2: 越南河内市还剑郡福新坊咸子关街77号 | AF2: 不作为一级经销商合作。Không hợp tác với tư cách nhà phân phối cấp 1. | AG2: =VLOOKUP(B2,'[1]Danh sách khách hàng'!$B:$G,6,FALSE) -> Số 77 Phố Hàm Tử Quan, Phường Phúc Tân, Quận Hoàn Kiếm, Thành phố Hà Nội, Việt Nam
A3: 2 | B3: 2141050030 | C3: 越南平明果蔬有限公司 | D3: CÔNG TY TNHH RAU QUẢ BÌNH MINH VIỆT NAM | E3: CONG TY TNHH RAU QUA BINH MINH VIET NAM | F3: 黎明水果 | G3: 0201640232 | H3: Tờ bản đồ số 15, Tổ dân phố Hạ, Phường An Hưng, Quận Hồng Bàng, Thành phố Hải Phòng, Việt Nam | I3: 0225.3528323 | J3: Ông NGUYỄN THÀNH TRUNG | K3: NGUYEN THANH TRUNG | L3: GIÁM ĐỐC | M3: 经理 | N3: Tờ bản đồ số 15, Thôn Hạ, Xã An Hưng, Huyện An Dương, Thành phố Hải Phòng, Việt Nam | O3: Anh Trung | P3: 090 4288089 | Q3: HAIPHONG ,VIETNAM | R3: 经常 | V3: rauquabinhminhvietnam@gmail.com | W3: =B3 -> 2141050030 | X3: Vietcombank - chi nhánh Nam Hải Phòng | Y3: 越南商业银行 - 南海防分行 | Z3: 1031 000 000 456 | AA3: 郑明黄 | AC3: 090 4288089 ，a Trung ， tờ bản đồ số 15, thôn Hạ, xã An Hưng, huyện An Dương, thành phố Hải Phòng. | AD3: 越南海防市鸿庞郡安兴坊下居民组第15号地图块 | AF3: 不作为一级经销商合作。Không hợp tác với tư cách nhà phân phối cấp 1. | AG3: =VLOOKUP(B3,'[1]Danh sách khách hàng'!$B:$G,6,FALSE) -> Tờ bản đồ số 15, Tổ dân phố Hạ, Phường An Hưng, Quận Hồng Bàng, Thành phố Hải Phòng, Việt Nam
A4: 3 | B4: 2141020110 | C4: 越南黄天发贸易有限公司 | D4: CÔNG TY TNHH THƯƠNG MẠI HOÀNG THIÊN PHÁT | E4: CONG TY TNHH THUONG MAI HOANG THIEN PHAT | F4: 黄天发 | G4: 0316353410 | H4: 387 Phan Văn Trị, Phường Bình Lợi Trung, TP Hồ Chí Minh, Việt Nam. | I4: 0939368123 | J4: TRAN MINH HOANG | K4: 陈明黄 | L4: TỔNG GIÁM ĐỐC | M4: 总经理 | N4: 189 nguyễn oanh p10 gò vấp， hcmc | O4: Hoàng | P4: 937778293 | Q4: CAT LAI PORT ,HO CHI MINH,VIETNAM | R4: 军区附近，每天晚上10点 | S4: 仓库与卸货点较远 | T4: Chị Liễu | U4: 906887847 | V4: Hoangthienphat368@gmail.com | W4: =B4 -> 2141020110 | X4: Ngân hàng TMCP Á Châu (ACB) | Y4: 亚洲贸易股份银行（ACB) | Z4: 1363638888 | AA4: 朱建君 | AD4: 越南胡志明市平盛郡潘文治路387号 | AF4: 订单生效之日起3个工作日内，乙方应支付订单金额的【50】%作为预付款；自产品到达越南目的港/站后3个工作日内，乙方应支付订单金额剩余的全部款项。甲方将在收到订单100%款项后送货到乙方指定的收货地点。 Trong vòng 03 ngày làm việc kể từ ngày đơn hàng có hiệu lực, Bên Mua phải thanh toán 【50】% giá trị đơn hàng dưới hình thức tiền tạm ứng; trong vòng 03 ngày làm việc kể từ ngày sản phẩm đến cảng/ga đích tại Việt Nam, Bên Mua phải thanh toán toàn bộ số tiền còn lại của đơn hàng. Bên Bán sẽ giao hàng đến địa điểm nhận hàng do Bên Mua chỉ định sau khi nhận được 100% giá trị thanh toán của đơn hàng. | AG4: =VLOOKUP(B4,'[1]Danh sách khách hàng'!$B:$G,6,FALSE) -> 387 Phan Văn Trị, Phường Bình Lợi Trung, TP Hồ Chí Minh, Việt Nam.
A5: 4 | B5: 2141030020 | C5: 越南谅山龙霞一成员有限公司 | D5: CÔNG TY TNHH MTV XUẤT NHẬP KHẨU HƯƠNG THỊNH LS | E5: CONG TY TNHH MTV XUAT NHAP KHAU HUONG THINH LS | F5: 龙霞 | G5: 4900905841 | H5: Số 132 đường Trần Phú, Phường Kỳ Lừa, Tỉnh Lạng Sơn, Việt Nam. | I5: 0357584099 | J5: Đỗ Thị Kim Anh | K5: Do Thi Kim Anh | L5: TỔNG GIÁM ĐỐC | M5: 总经理 | N5: 132 đường Trần Phú thành phố Lạng Sơn | O5: Anh Long | P5: 942854827 | Q5: HUU NGHI, LANG SON ,VIETNAM | R5: 经常 | V5: dothikimanh2801@gmail.com | W5: =B5 -> 2141030020 | X5: Ngân hàng Sài Gòn Thương Tín (STB) | Y5: 越南西贡商业银行 | Z5: 30093866491 | AA5: 阮文忠 | AD5: 越南谅山省谅山市奇劳坊陈富路132号 | AF5: 订单生效之日起3个工作日内，乙方应支付订单金额的【50】%作为预付款；自产品到达越南目的港/站后3个工作日内，乙方应支付订单金额剩余的全部款项。甲方将在收到订单100%款项后送货到乙方指定的收货地点。 Trong vòng 03 ngày làm việc kể từ ngày đơn hàng có hiệu lực, Bên Mua phải thanh toán 【50】% giá trị đơn hàng dưới hình thức tiền tạm ứng; trong vòng 03 ngày làm việc kể từ ngày sản phẩm đến cảng/ga đích tại Việt Nam, Bên Mua phải thanh toán toàn bộ số tiền còn lại của đơn hàng. Bên Bán sẽ giao hàng đến địa điểm nhận hàng do Bên Mua chỉ định sau khi nhận được 100% giá trị thanh toán của đơn hàng. | AG5: =VLOOKUP(B5,'[1]Danh sách khách hàng'!$B:$G,6,FALSE) -> Số 132 đường Trần Phú, Phường Kỳ Lừa, Tỉnh Lạng Sơn, Việt Nam.
A6: 5 | B6: 2141010070 | C6: 越南食品进出口服务贸易有限公司 | D6: CÔNG TY TNHH THƯƠNG MẠI DỊCH VỤ XUẤT NHẬP KHẨU VIỆT FOODS | E6: CONG TY TNHH THUONG MAI DICH VU XUAT NHAP KHAU VIET FOODS | F6: 新俊芳 | G6: 0110615246 | H6: Thôn Đông Trạch, Xã Nam Phù, TP Hà Nội, Việt Nam. | I6: 0966506434 | J6: Nguyễn Đức Thành | K6: Nguyen Duc Thanh | L6: GIÁM ĐỐC | M6: 经理 | N6: Khu khả lễ.phường võ cường. Thành phố bắc ninh | O6: Anh Thành Tuấn Phương | P6: 098 4968999 | Q6: CHI MA, LANG SON，VIETNAM/HAIPHONG ,VIETNAM | R6: 每天晚上10点 0363333888-Binh - Kho hàng | V6: congtyvietfood68@gmail.com | W6: =B6 -> 2141010070 | X6: Ngân hàng TMCP Đầu tư và Phát triển Việt Nam (BIDV) | Y6: 越南投资和发展股份制商业银行（BIDV） | Z6: 8600022041 | AA6: 郑明黄 | AD6: 越南河内市南扶乡东泽村 | AF6: 不作为一级经销商合作。Không hợp tác với tư cách nhà phân phối cấp 1. | AG6: =VLOOKUP(B6,'[1]Danh sách khách hàng'!$B:$G,6,FALSE) -> Thôn Đông Trạch, Xã Nam Phù, TP Hà Nội, Việt Nam.
A7: 6 | B7: 2141110010 | C7: 越南阮氏娇庄 | D7: NGUYỄN THỊ KIỀU TRANG | E7: NGUYEN THI KIEU TRANG | F7: 阮氏娇庄 | G7: 8712031066-001 | H7: Số 77, Nguyễn Tất Thành, Phường Khai Quang, Thành phố Vĩnh Yên, Tỉnh Vĩnh Phúc, Việt Nam | I7: 0365634443 | J7: Nguyễn Thị Kiều Trang | K7: Nguyen Thi Kieu Trang | L7: GIÁM ĐỐC | M7: 经理 | N7: 77 Nguyễn Tất Thành, P. Khai Quang, TP Vĩnh Yên, tỉnh Vĩnh Phúc | Q7: HAIPHONG ,VIETNAM | R7: 经常 | W7: =B7 -> 2141110010 | X7: Ngân hàng Teckcombank -NGUYEN THI KIEU TRANG | Y7: 越南科技商业股份银行（Techcombank ) | Z7: 9036821692011 | AA7: 阮文忠 | AC7: 永福 | AD7: 越南永福省永安市开光坊阮必成路77号 | AF7: 不作为一级经销商合作。Không hợp tác với tư cách nhà phân phối cấp 1. | AG7: =VLOOKUP(B7,'[1]Danh sách khách hàng'!$B:$G,6,FALSE) -> Số 77, Nguyễn Tất Thành, Phường Khai Quang, Thành phố Vĩnh Yên, Tỉnh Vĩnh Phúc, Việt Nam
A8: 7 | B8: 2141090020 | C8: 越南武德贵 | D8: VŨ ĐỨC QUÝ | E8: VU DUC QUY | F8: 武德贵 | H8: Ngõ 276, khối 1 , Vĩnh Tân , thành phố Vinh, Nghệ An | I8: 0968416361 | J8: VŨ ĐỨC QUÝ | K8: VU DUC QUY | N8: Khối 1 (nhà ông Nguyễn Văn Hưng, thửa đất số 668, tờ bản đồ số 06) phường Vinh Tân, thành phố Vinh, tỉnh Nghệ An | Q8: HAIPHONG ,VIETNAM | R8: 经常 | W8: =B8 -> 2141090020 | X8: Vietcombank trự sở CN Nghệ An | Y8: 越南商业银行 - 乂安分行 | Z8: 0101001169857 / Nguyễn Thị Nguyệt | AA8: 郑明黄 | AC8: 义安 | AD8: 越南乂安省荣市永新坊第1街区276号巷 | AF8: 不作为一级经销商合作。Không hợp tác với tư cách nhà phân phối cấp 1. | AG8: =VLOOKUP(B8,'[1]Danh sách khách hàng'!$B:$G,6,FALSE) -> Ngõ 276, khối 1 , Vĩnh Tân , thành phố Vinh, Nghệ An
A9: 8 | B9: 2141100020 | C9: 越南天龙发有限公司 | D9: CÔNG TY TNHH THIÊN LONG PHÁT VN | E9: CONG TY TNHH THIEN LONG PHAT VN | F9: 天龙发 | G9: 3703171766 | H9: Số 170A, Đường Số 1, Khu 2, Phường Hoà Phú, Thành phố Thủ Dầu Một, Tỉnh Bình Dương, Việt Nam | I9: 0373098579 | J9: Lê Mộng Kha | K9: 黎梦珂 | L9: GIÁM ĐỐC | M9: 总经理 | N9: VSIP2 Đường D4, Tổ 1, KP1, Vĩnh Tân, Tân Uyên, Bình Dương | P9: 866471453 | Q9: CAT LAI PORT ,HO CHI MINH,VIETNAM | R9: 经常 | W9: =B9 -> 2141100020 | X9: Ngân hàng TMCP công thương Việt Nam,Chi nhánh KCN Bình Dương | Y9: 越南工商银行平阳工业区分行 | Z9: 111002958480 | AA9: 朱建君 | AD9: 越南平阳省土龙木市和富坊第2区1号路170A号 | AF9: 不作为一级经销商合作。Không hợp tác với tư cách nhà phân phối cấp 1. | AG9: =VLOOKUP(B9,'[1]Danh sách khách hàng'!$B:$G,6,FALSE) -> Số 170A, Đường Số 1, Khu 2, Phường Hoà Phú, Thành phố Thủ Dầu Một, Tỉnh Bình Dương, Việt Nam
A10: 9 | B10: 2141030030 | C10: 越南青青有限责任公司 | D10: CÔNG TY TNHH KINH DOANH THƯƠNG MẠI THANH THANH | E10: CONG TY TNHH KINH DOANH THUONG MAI THANH THANH | F10: 青青 | G10: 4900891726 | H10: Số 164, đường Hoàng Văn Thụ, khu Lò Rèn, Thị trấn Đồng Đăng, Huyện Cao Lộc, Tỉnh Lạng Sơn, Việt Nam | J10: Hà Thị Thanh | K10: Ha Thi Thanh | L10: GIÁM ĐỐC | M10: 经理 | N10: Số 164, đường Hoàng Văn Thụ, khu Lò Rèn, Thị trấn Đồng Đăng, Huyện Cao Lộc, Tỉnh Lạng Sơn, Việt Nam | P10: ‘0352139888 | Q10: HUU NGHI, LANG SON ,VIETNAM | R10: 经常 | W10: =B10 -> 2141030030 | X10: Ngân Hàng TMCP Công Thương Việt Nam (Vietinbank) | Y10: 越南工商银行 | Z10: 115604323999 | AA10: 阮文忠 | AD10: 越南谅山省高禄县同登市镇炉炼区黄文树路164号 | AF10: 不作为一级经销商合作。Không hợp tác với tư cách nhà phân phối cấp 1. | AG10: =VLOOKUP(B10,'[1]Danh sách khách hàng'!$B:$G,6,FALSE) -> Số 164, đường Hoàng Văn Thụ, khu Lò Rèn, Thị trấn Đồng Đăng, Huyện Cao Lộc, Tỉnh Lạng Sơn, Việt Nam
A11: 10 | B11: 2141020030 | C11: 越南味丹股份有限公司（总部-总仓） | D11: CÔNG TY CỔ PHẦN HỮU HẠN VEDAN VIỆT NAM | E11: CONG TY CO PHAN HUU HAN VEDAN VIET NAM | F11: 味丹 | G11: 3600239719 | H11: Quốc lộ 51, Ấp 1A, Xã Phước Thái, Đồng Nai, Việt Nam. | J11: TANG DAW SEN | K11: TANG DAW SEN | L11: GIÁM ĐỐC | M11: 总经理 | N11: Quốc lộ 51, Ấp 1A, Xã Phước Thái, Huyện Long Thành, Tỉnh Đồng Nai, Việt Nam. | Q11: CAT LAI PORT ,HO CHI MINH,VIETNAM | R11: 经常 | V11: huyen-tt@vedaninternational.com | W11: =B11 -> 2141020030 | AA11: 朱建君 | AD11: 越南同奈省福泰乡1A邑51号国道 | AF11: 订单生效之日起14个工作日内，乙方应支付订单金额的【100】%作为预付款；自产品到达越南目的港/站后3个工作日内，乙方应支付订单金额剩余的全部款项。甲方将在收到订单100%款项后送货到乙方指定的收货地点。 Trong vòng 14 ngày làm việc kể từ ngày đơn hàng có hiệu lực, Bên Mua phải thanh toán 【100】% giá trị đơn hàng dưới hình thức tiền tạm ứng; trong vòng 03 ngày làm việc kể từ ngày sản phẩm đến cảng/ga đích tại Việt Nam, Bên Mua phải thanh toán toàn bộ số tiền còn lại của đơn hàng. Bên Bán sẽ giao hàng đến địa điểm nhận hàng do Bên Mua chỉ định sau khi nhận được 100% giá trị thanh toán của đơn hàng. | AG11: =VLOOKUP(B11,'[1]Danh sách khách hàng'!$B:$G,6,FALSE) -> Quốc lộ 51, Ấp 1A, Xã Phước Thái, Đồng Nai, Việt Nam.
A12: 11 | B12: 2141020130 | C12: 越南智越发贸易服务及生产有限公司 | D12: CÔNG TY TNHH THƯƠNG MẠI DỊCH VỤ VÀ SẢN XUẤT TRÍ VIỆT PHÁT | E12: CONG TY TNHH THUONG MAI DICH VU VA SAN XUAT TRI VIET PHAT | F12: 智越发 | G12: 0312096843 | H12: Số 81 Đường Tân Hòa 2, Khu phố 24, Phường Tăng Nhơn Phú, TP Hồ Chí Minh, Việt Nam. | J12: NGUYỄN THỊ VÂN ANH | K12: NGUYEN THI VAN ANH | L12: GIÁM ĐỐC | M12: 总经理 | N12: 178 Đường Long Thuận, Long Phước, TP Thủ Đức, HCM (quận 9 cũ) | O12: Mr. Tân | P12: 0977905020 (kho) | Q12: CAT LAI PORT ,HO CHI MINH,VIETNAM | R12: 经常 | W12: =B12 -> 2141020130 | X12: BIDV-Ngân hàng Thương mại cổ phần Đầu tư và Phát triển Việt Nam- Chi nhánh Đong Sài Gòn | Y12: 越南投资和发展股份制商业银行（BIDV）-东西贡分行 | Z12: 3141324180 | AA12: 朱建君 | AD12: 越南胡志明市增仁富坊24街区新和2路81号 | AF12: 买方（乙方）须在签订采购订单后立即支付订单总金额的 50%，剩余的 50% 款项必须在收货前（卖方交货前）全部付清。买方付款后，须通过电子邮件或在线聊天软件向卖方提供有效的付款凭证；卖方只有在收到足额款项或有效付款凭证后，才会安排生产、检验、检疫及进出口手续。同时，任何因转账产生的费用（包括但不限于中转行费用）均由买方（乙方）承担。 Bên B thanh toán cho Bên A trước 50% tổng giá trị đơn hàng ngay khi ký Đơn đặt hàng, và 50% còn lại thanh toán hết trước khi nhận hàng (trước khi Bên A giao hàng). Sau khi chuyển khoản, Bên B cần cung cấp chứng từ thanh toán hợp lệ qua email hoặc ứng dụng trò chuyện trực tuyến; Bên A chỉ sắp xếp các thủ tục sản xuất, kiểm tra, kiểm dịch, xuất nhập khẩu sau khi nhận đủ số tiền hoặc chứng từ thanh toán này. Đồng thời, bất kỳ khoản phí chuyển khoản nào phát sinh (bao gồm nhưng không giới hạn ở phí ngân hàng trung chuyển) sẽ hoàn toàn do Bên B chịu. | AG12: =VLOOKUP(B12,'[1]Danh sách khách hàng'!$B:$G,6,FALSE) -> Số 81 Đường Tân Hòa 2, Khu phố 24, Phường Tăng Nhơn Phú, TP Hồ Chí Minh, Việt Nam.
A13: 12 | B13: 2141010080 | C13: 越南全德贸易投资有限公司 | D13: CÔNG TY TNHH ĐẦU TƯ THƯƠNG MẠI TOÀN ĐỨC | E13: CONG TY TNHH DAU TU THUONG MAI TOAN DUC | F13: 全德 | G13: 0106667555 | H13: Số 5, ngõ 2 phố Đại Linh, Phường Đại Mỗ, TP Hà Nội, Việt Nam. | I13: 0967260022 | J13: ĐỖ VĂN LƯƠNG | K13: DO VAN LUONG | L13: GIÁM ĐỐC | M13: 总经理 | N13: D06-NV4 ô 033, khu D, KĐT Gleximco - Lê Trọng Tấn, Xã La Phù, Huyện Hoài Đức, Thành Phố Hà Nội, Việt Nam | O13: ĐỖ VĂN LƯƠNG | P13: 0967260022 | Q13: HUU NGHI, LANG SON ,VIETNAM， 未来火车 | R13: 经常 | U13: '0967260022 | V13: toanducfoodhd@gmail.com | W13: =B13 -> 2141010080 | X13: TECHCOMBANK-Ngân hàng Thương mại cổ phần Kỹ Thương Việt Nam | Y13: 越南科技商业股份银行 | Z13: 19128691892686/19028691892010 | AA13: 郑明黄 | AB13: toanducfood@gmail.com 这张邮箱是公司的，邮箱在row V是收到发票 | AD13: 越南河内市大姥坊大灵街2号巷5号 | AF13: 订单生效之日起3个工作日内，乙方应支付订单金额的【50】%作为预付款；自产品到达越南目的港/站后3个工作日内，乙方应支付订单金额剩余的全部款项。甲方将在收到订单100%款项后送货到乙方指定的收货地点。 Trong vòng 03 ngày làm việc kể từ ngày đơn hàng có hiệu lực, Bên Mua phải thanh toán 【50】% giá trị đơn hàng dưới hình thức tiền tạm ứng; trong vòng 03 ngày làm việc kể từ ngày sản phẩm đến cảng/ga đích tại Việt Nam, Bên Mua phải thanh toán toàn bộ số tiền còn lại của đơn hàng. Bên Bán sẽ giao hàng đến địa điểm nhận hàng do Bên Mua chỉ định sau khi nhận được 100% giá trị thanh toán của đơn hàng. | AG13: =VLOOKUP(B13,'[1]Danh sách khách hàng'!$B:$G,6,FALSE) -> Số 5, ngõ 2 phố Đại Linh, Phường Đại Mỗ, TP Hà Nội, Việt Nam.
A14: 13 | B14: 2141070020 | C14: 越南通达发一成员贸易服务有限公司 | D14: CÔNG TY TNHH MTV THƯƠNG MẠI DỊCH VỤ THÔNG ĐẠT PHÁT | E14: CONG TY TNHH MTV THUONG MAI DICH VU THONG DAT PHAT | F14: 通达发 | G14: 3603857255 | H14: 19/5A, tổ 20, Khu Phố 3, Phường Bửu Long, Thành phố Biên Hoà, Tỉnh Đồng Nai, Việt Nam | I14: 0379774123 | J14: CHỀ ÁNH KIM | K14: CHE ANH KIM | L14: GIÁM ĐỐC | M14: 总经理 | N14: Cụm công nghiệp bảy mẫu thị trấn thái hoà thành phố tân uyên tỉnh Bình Dương | O14: Chị Kim | P14: 379774123 | Q14: CAT LAI PORT ,HO CHI MINH,VIETNAM | R14: 经常 | U14: 379774123 | V14: Thongdatphat22@gmail.com | W14: =B14 -> 2141070020 | X14: BIDV-Ngân hàng Thương mại cổ phần Đầu tư và Phát triển Việt Nam | Y14: 越南投资和发展股份制商业银行（BIDV） | Z14: 67210002953995 | AA14: 朱建君 | AD14: 越南同奈省边和市宝龙坊第3街区20组19/5A号 | AF14: 不作为一级经销商合作。Không hợp tác với tư cách nhà phân phối cấp 1. | AG14: =VLOOKUP(B14,'[1]Danh sách khách hàng'!$B:$G,6,FALSE) -> 19/5A, tổ 20, Khu Phố 3, Phường Bửu Long, Thành phố Biên Hoà, Tỉnh Đồng Nai, Việt Nam
A15: 14 | B15: 2141020020 | C15: 越南VP进出口贸易有限公司 | D15: CÔNG TY TNHH THƯƠNG MẠI THỰC PHẨM VINH PHÁT | E15: CONG TY TNHH THUONG MAI THUC PHAM VINH PHAT | F15: 越南VP | G15: 0310487418 | H15: 450/1 Hòa Hảo, Phường Diên Hồng, TP Hồ Chí Minh, Việt Nam. | I15: 08 39245355 | J15: LIÊU BÁ SÂM | K15: LIEU BA SAM | L15: GIÁM ĐỐC | M15: 总经理 | N15: 252/18P Phan Anh, phường Hiệp Tân, quận Tân Phú | O15: Liên hệ Anh Bân : +84 903003877 | P15: 903003877 | Q15: CAT LAI PORT ,HO CHI MINH,VIETNAM | R15: 经常 | W15: =B15 -> 2141020020 | X15: ACB – PGD Hàm Tử | Y15: 亚洲商业银行 | Z15: 810928 | AA15: 朱建君 | AD15: 越南胡志明市演红坊好好路450/1号 | AF15: 订单生效之日起3个工作日内，乙方应支付订单金额的【100】%作为预付款；自产品到达越南目的港/站后3个工作日内，乙方应支付订单金额剩余的全部款项。甲方将在收到订单100%款项后送货到乙方指定的收货地点。 Trong vòng 03 ngày làm việc kể từ ngày đơn hàng có hiệu lực, Bên Mua phải thanh toán 【100】% giá trị đơn hàng dưới hình thức tiền tạm ứng; trong vòng 03 ngày làm việc kể từ ngày sản phẩm đến cảng/ga đích tại Việt Nam, Bên Mua phải thanh toán toàn bộ số tiền còn lại của đơn hàng. Bên Bán sẽ giao hàng đến địa điểm nhận hàng do Bên Mua chỉ định sau khi nhận được 100% giá trị thanh toán của đơn hàng. | AG15: =VLOOKUP(B15,'[1]Danh sách khách hàng'!$B:$G,6,FALSE) -> 450/1 Hòa Hảo, Phường Diên Hồng, TP Hồ Chí Minh, Việt Nam.
A16: 15 | B16: 2141020140 | C16: 越南芳云进出口有限公司 | D16: CÔNG TY TNHH MTV XNK PHONG VÂN | E16: CONG TY TNHH MTV XNK PHONG VAN | F16: 芳云 | G16: 0310196137 | H16: 20 Huỳnh Thị Bảy, Ấp 1, Xã Tân Nhựt, TP Hồ Chí Minh, Việt Nam. | I16: 0905586622 | J16: NGO THI HUONG HOA | K16: NGO THI HUONG HOA | L16: GIÁM ĐỐC | M16: 总经理 | N16: 168 Quang Trung, Phường 10, Gò vấp, TP. Hồ Chí Minh, Việt Nam. | O16: Bùi Thị Thu Hằng | P16: '0905586622 | Q16: CAT LAI PORT ,HO CHI MINH,VIETNAM | R16: 经常 | U16: 905586622 | V16: hoadon@phongvanfc.com | W16: =B16 -> 2141020140 | X16: Ngân hàng TMCP Công Thương Việt Nam(Vietinbank) – Chi nhánh 8 | Y16: 越南工商银行-第8分行 | Z16: 118002711993 | AA16: 朱建君 | AD16: 越南胡志明市新日乡1邑黄氏七路20号 | AF16: 订单生效之日起3个工作日内，乙方应支付订单金额的【50】%作为预付款；自产品到达越南目的港/站后3个工作日内，乙方应支付订单金额剩余的全部款项。甲方将在收到订单100%款项后送货到乙方指定的收货地点。 Trong vòng 03 ngày làm việc kể từ ngày đơn hàng có hiệu lực, Bên Mua phải thanh toán 【50】% giá trị đơn hàng dưới hình thức tiền tạm ứng; trong vòng 03 ngày làm việc kể từ ngày sản phẩm đến cảng/ga đích tại Việt Nam, Bên Mua phải thanh toán toàn bộ số tiền còn lại của đơn hàng. Bên Bán sẽ giao hàng đến địa điểm nhận hàng do Bên Mua chỉ định sau khi nhận được 100% giá trị thanh toán của đơn hàng. | AG16: =VLOOKUP(B16,'[1]Danh sách khách hàng'!$B:$G,6,FALSE) -> 20 Huỳnh Thị Bảy, Ấp 1, Xã Tân Nhựt, TP Hồ Chí Minh, Việt Nam.
A17: 16 | B17: 2141010090 | C17: 越南食品进出口服务贸易有限公司（工业） | D17: CÔNG TY TNHH THƯƠNG MẠI DỊCH VỤ XUẤT NHẬP KHẨU VIỆT FOODS(CÔNG NGHIỆP) | E17: CONG TY TNHH THUONG MAI DICH VU XUAT NHAP KHAU VIET FOODS | F17: 新俊芳 | G17: 0110615246 | H17: Thôn Đông Trạch, Xã Nam Phù, TP Hà Nội, Việt Nam | I17: 0966506434 | J17: Nguyễn Đức Thành | K17: Nguyen Duc Thanh | L17: GIÁM ĐỐC | M17: 经理 | N17: Khu khả lễ.phường võ cường. Thành phố bắc ninh | O17: Anh Thành Tuấn Phương | P17: 984968999 | Q17: CHI MA, LANG SON，VIETNAM/HAIPHONG ,VIETNAM | R17: 每天晚上10点 | S17: 0 | U17: 0 | V17: congtyvietfood68@gmail.com | W17: =B17 -> 2141010090 | X17: Ngân hàng TMCP Đầu tư và Phát triển Việt Nam (BIDV) | Y17: 越南投资和发展股份制商业银行（BIDV） | Z17: 8600022041 | AA17: 郑明黄 | AB17: 0 | AC17: 0 | AD17: 越南河内市南扶乡东泽村 | AF17: 不作为一级经销商合作。Không hợp tác với tư cách nhà phân phối cấp 1. | AG17: =VLOOKUP(B17,'[1]Danh sách khách hàng'!$B:$G,6,FALSE) -> Thôn Đông Trạch, Xã Nam Phù, TP Hà Nội, Việt Nam
A18: 17 | B18: 2141020160 | C18: 越南诺萨食品股份公司（工业） | D18: CÔNG TY CỔ PHẦN NOSAFOOD(CÔNG NGHIỆP) | E18: NOSAFOOD JOINT STOCK COMPANY | F18: NOSAFOOD(工业) | G18: 0303841040 | H18: E4/20 Nguyễn Hữu Trí, Xã Tân Nhựt, Thành phố Hồ Chí Minh, Việt Nam. | I18: 02862728888 | J18: HO JOONG | K18: HO JOONG | L18: GIÁM ĐỐC | M18: 总经理 | N18: Lô D3/1-4 đường VL7, KCN Vĩnh Lộc 2, xã Long Hiệp, huyện Bến Lức, Long An (cổng KCN đi thẳng đến cuối đường rẽ trái, đi tiếp đến cuối đường) | Q18: CAT LAI PORT ,HO CHI MINH,VIETNAM | R18: 经常 | T18: 0919931349 Ngọc | V18: hanhchinh@nosafood.com | W18: =B18 -> 2141020160 | X18: Ngân hàng Agribank, CN Nam Sài Gòn | Y18: 农业银行南西贡支行（VBAAVNVX） | Z18: 6160201014420 | AA18: 朱建君 | AD18: 越南胡志明市新日乡阮友智路E4/20号 | AF18: 不作为一级经销商合作。Không hợp tác với tư cách nhà phân phối cấp 1. | AG18: =VLOOKUP(B18,'[1]Danh sách khách hàng'!$B:$G,6,FALSE) -> E4/20 Nguyễn Hữu Trí, Xã Tân Nhựt, Thành phố Hồ Chí Minh, Việt Nam.
A19: 18 | B19: 2141020150 | C19: 越南诺萨食品股份公司（OEM） | D19: CÔNG TY CỔ PHẦN NOSAFOOD(OEM) | E19: NOSAFOOD JOINT STOCK COMPANY | F19: NOSAFOOD(OEM) | G19: 0303841040 | H19: E4/20 Nguyễn Hữu Trí, Thị Trấn Tân Túc, Huyện Bình Chánh, Thành phố Hồ Chí Minh, Việt Nam | I19: 02862728888 | J19: HO JOONG | K19: HO JOONG | L19: GIÁM ĐỐC | M19: 总经理 | N19: Lô D3/1-4 đường VL7, KCN Vĩnh Lộc 2, xã Long Hiệp, huyện Bến Lức, Long An (cổng KCN đi thẳng đến cuối đường rẽ trái, đi tiếp đến cuối đường) | Q19: CAT LAI PORT ,HO CHI MINH,VIETNAM | R19: 经常 | V19: hanhchinh@nosafood.com | W19: =B19 -> 2141020150 | X19: Ngân hàng Agribank, CN Nam Sài Gòn | Y19: 农业银行南西贡支行（VBAAVNVX） | Z19: 6160201014420 | AA19: 朱建君 | AD19: 越南胡志明市平政县新足市镇阮友智路E4/20号 | AF19: 不作为一级经销商合作。Không hợp tác với tư cách nhà phân phối cấp 1. | AG19: =VLOOKUP(B19,'[1]Danh sách khách hàng'!$B:$G,6,FALSE) -> E4/20 Nguyễn Hữu Trí, Thị Trấn Tân Túc, Huyện Bình Chánh, Thành phố Hồ Chí Minh, Việt Nam
A20: 19 | B20: 2141010110 | C20: 越南同心投资贸易有限公司 | D20: CÔNG TY TNHH ĐẦU TƯ VÀ THƯƠNG MẠI ĐỒNG TÂM | F20: 同心 | G20: 0105032376 | H20: Số 12, ngách 12, ngõ 23, phố Bồ Đề, tổ 5, Phường Bồ Đề, TP Hà Nội, Việt Nam. | J20: VƯƠNG THỊ THU THỦY | K20: VUONG THI THU THUY | L20: GIÁM ĐỐC | M20: 总经理 | N20: Phường Bồ Đề, quận Long Biên, thành phố Hà Nội, Việt Nam | O20: Ms Duyên | P20: . 0376654989 . | V20: salesdongtamfood@gmail.com | W20: =B20 -> 2141010110 | AA20: 郑明黄 | AD20: 越南河内市菩提坊第5组菩提街23号巷12支巷12号 | AF20: 不作为一级经销商合作。Không hợp tác với tư cách nhà phân phối cấp 1. | AG20: =VLOOKUP(B20,'[1]Danh sách khách hàng'!$B:$G,6,FALSE) -> Số 12, ngách 12, ngõ 23, phố Bồ Đề, tổ 5, Phường Bồ Đề, TP Hà Nội, Việt Nam.
A21: 20 | C21: 越南新绿食品有限公司 | D21: CÔNG TY TNHH NEW GREEN FOOD | E21: CONG TY TNHH NEW GREEN FOOD | F21: MISA新绿食品 | G21: 201878595 | H21: #N/A | I21: 02258831983 | J21: NGUYEN THANH LONG | K21: NGUYEN THANH LONG | L21: GIÁM ĐỐC | M21: 总经理 | T21: Ms Thương | U21: 971350969 | V21: lanhuonght88.hp@gmail.com | W21: =B21 -> 0 | AD21: #N/A | AF21: 不作为一级经销商合作。Không hợp tác với tư cách nhà phân phối cấp 1. | AG21: =VLOOKUP(B21,'[1]Danh sách khách hàng'!$B:$G,6,FALSE) -> #N/A
A22: 21 | B22: 2141010100 | C22: 越南安库生产贸易和服务有限公司 | D22: CÔNG TY TNHH SẢN XUẤT THƯƠNG MẠI VÀ DỊCH VỤ AN KHUÊ | F22: AN KHUE 安库 | G22: 0110318349 | H22: Số 36, Đường Long Biên 2, Phường Bồ Đề, TP Hà Nội, Việt Nam. | I22: 086 9813026 | J22: TRỊNH NGỌC MINH | K22: TRINH NGOC MINH | L22: GIÁM ĐỐC | M22: 总经理 | N22: Số 374A đường Hùng Vương, phường Hùng Vương, quận Hồng Bàng, thành phố Hải Phòng, Việt Nam: 086 9813026: 9,840 kg——40箱 | W22: =B22 -> 2141010100 | AD22: 越南河内市菩提坊龙编2路36号 | AF22: 不作为一级经销商合作。Không hợp tác với tư cách nhà phân phối cấp 1. | AG22: =VLOOKUP(B22,'[1]Danh sách khách hàng'!$B:$G,6,FALSE) -> Số 36, Đường Long Biên 2, Phường Bồ Đề, TP Hà Nội, Việt Nam.
A23: 22 | C23: 黄天发（胡志明工业客户-番茄酱） | H23: #N/A | L23: GIÁM ĐỐC | M23: 总经理 | N23: 189 nguyễn oanh p10 gò vấp， hcmc：Anh Hoàng : 0937778293 : 1,968kg——8箱 | W23: =B23 -> 0 | AD23: #N/A | AF23: 不作为一级经销商合作。Không hợp tác với tư cách nhà phân phối cấp 1. | AG23: =VLOOKUP(B23,'[1]Danh sách khách hàng'!$B:$G,6,FALSE) -> #N/A
A24: 23 | B24: 2141110020 | C24: 越南惠嘉进出口有限公司 | D24: CÔNG TY TNHH MTV XUẤT NHẬP KHẨU HUỆ GIA | E24: CONG TY TNHH MTV XUAT NHAP KHAU HUE GIA | F24: 惠嘉 | G24: 2500728577 | H24: Số 136, đường Tôn Đức Thắng, Phường Vĩnh Phúc, Phú Thọ, Việt Nam. | J24: Nguyễn Thị Kiều Trang | K24: Nguyen Thi Kieu Trang | L24: GIÁM ĐỐC | M24: 总经理 | N24: 77 Nguyễn Tất Thành, P. Khai Quang, TP Vĩnh Yên, tỉnh Vĩnh Phúc | T24: Nguyễn Thị Kiều Trang | V24: kieutrang281097@gmail.com | W24: =B24 -> 2141110020 | X24: Nngân hàng TMCP Công thương Việt Nam chi nhánh Vĩnh Phúc | Y24: 越南工商银行永福分行 | Z24: 111601221555 | AA24: 阮文忠 | AD24: 越南富寿省永福坊孙德胜路136号 | AF24: 订单生效之日起3个工作日内，乙方应支付订单金额的【50】%作为预付款；自产品到达越南目的港/站后3个工作日内，乙方应支付订单金额剩余的全部款项。甲方将在收到订单100%款项后送货到乙方指定的收货地点。 Trong vòng 03 ngày làm việc kể từ ngày đơn hàng có hiệu lực, Bên Mua phải thanh toán 【50】% giá trị đơn hàng dưới hình thức tiền tạm ứng; trong vòng 03 ngày làm việc kể từ ngày sản phẩm đến cảng/ga đích tại Việt Nam, Bên Mua phải thanh toán toàn bộ số tiền còn lại của đơn hàng. Bên Bán sẽ giao hàng đến địa điểm nhận hàng do Bên Mua chỉ định sau khi nhận được 100% giá trị thanh toán của đơn hàng. | AG24: =VLOOKUP(B24,'[1]Danh sách khách hàng'!$B:$G,6,FALSE) -> Số 136, đường Tôn Đức Thắng, Phường Vĩnh Phúc, Phú Thọ, Việt Nam.
A25: 24 | B25: 2141100030 | C25: 越南邻客贸易有限公司 | D25: CÔNG TY TNHH THƯƠNG MẠI LIN KE | G25: 3703139459 | H25: HT1-1B Lô F8,F9, Đường Bùi Thị Xuân, Khu Đô Thị Mới, Phường Bình Dương, TP Hồ Chí Minh, Việt Nam. | I25: '0528062362 | J25: NGUYỄN THỊ LAN | K25: NGUYEN THI LAN | L25: GIÁM ĐỐC | M25: 总经理 | N25: Số 49, Đường Truông Bồng Bông, Phường Định Hòa, Thành phố Thủ Dầu Một, Tỉnh Bình Dương | P25: '0899021119 | V25: congtytnhhlinke@gmail.com | W25: =B25 -> 2141100030 | X25: Ngân hàng Vietcombank-chi nhánh Đông Bình Dương | Y25: 越南商业银行-东平阳分行 | Z25: 1039912723 | AA25: 朱建君 | AD25: 越南胡志明市平阳坊新市区裴氏春路F8、F9地块HT1-1B | AF25: 订单生效之日起3个工作日内，乙方应支付订单金额的【50】%作为预付款；自产品到达越南目的港/站后3个工作日内，乙方应支付订单金额剩余的全部款项。甲方将在收到订单100%款项后送货到乙方指定的收货地点。 Trong vòng 03 ngày làm việc kể từ ngày đơn hàng có hiệu lực, Bên Mua phải thanh toán 【50】% giá trị đơn hàng dưới hình thức tiền tạm ứng; trong vòng 03 ngày làm việc kể từ ngày sản phẩm đến cảng/ga đích tại Việt Nam, Bên Mua phải thanh toán toàn bộ số tiền còn lại của đơn hàng. Bên Bán sẽ giao hàng đến địa điểm nhận hàng do Bên Mua chỉ định sau khi nhận được 100% giá trị thanh toán của đơn hàng. | AG25: =VLOOKUP(B25,'[1]Danh sách khách hàng'!$B:$G,6,FALSE) -> HT1-1B Lô F8,F9, Đường Bùi Thị Xuân, Khu Đô Thị Mới, Phường Bình Dương, TP Hồ Chí Minh, Việt Nam.
A26: 25 | B26: 2141030060 | C26: 越南荷青综合贸易有限公司 | D26: CÔNG TY TNHH KINH DOANH TỔNG HỢP HÀ THANH | E26: CONG TY TNHH KINH DOANH TONG HOP HA THANH | F26: 荷青 | G26: 4900918008 | H26: Số 75, đường Hoàng Văn Thụ, khu Lò Rèn, Xã Đồng Đăng, Lạng Sơn, Việt Nam. | I26: ‘0969049348 | J26: HÀ THỊ THANH | K26: HA THI THANH | L26: GIÁM ĐỐC | M26: 总经理 | N26: Số 164, đường Hoàng Văn Thụ, khu Lò Rèn, Thị trấn Đồng Đăng, Huyện Cao Lộc, Tỉnh Lạng Sơn, Việt Nam | V26: ctyhathanh8689@gmail.com. | W26: =B26 -> 2141030060 | X26: Ngân Hàng TMCP Công Thương Việt Nam CN LẠNG SƠN -PGD ĐỒNG ĐĂNG | Z26: 118190139999 | AA26: 阮文忠 | AD26: 越南谅山省同登乡炉炼区黄文树路75号 | AF26: 订单生效之日起3个工作日内，乙方应支付订单金额的【50】%作为预付款；自产品到达越南目的港/站后3个工作日内，乙方应支付订单金额剩余的全部款项。甲方将在收到订单100%款项后送货到乙方指定的收货地点。 Trong vòng 03 ngày làm việc kể từ ngày đơn hàng có hiệu lực, Bên Mua phải thanh toán 【50】% giá trị đơn hàng dưới hình thức tiền tạm ứng; trong vòng 03 ngày làm việc kể từ ngày sản phẩm đến cảng/ga đích tại Việt Nam, Bên Mua phải thanh toán toàn bộ số tiền còn lại của đơn hàng. Bên Bán sẽ giao hàng đến địa điểm nhận hàng do Bên Mua chỉ định sau khi nhận được 100% giá trị thanh toán của đơn hàng. | AG26: =VLOOKUP(B26,'[1]Danh sách khách hàng'!$B:$G,6,FALSE) -> Số 75, đường Hoàng Văn Thụ, khu Lò Rèn, Xã Đồng Đăng, Lạng Sơn, Việt Nam.
A27: 26 | B27: 2141120020 | C27: 海洋安军一成员责任有限公司 | D27: CÔNG TY TNHH MTV AN QUÂN HẢI DƯƠNG | E27: CONG TY TNHH MTV AN QUAN HAI DUONG | F27: 海阳 | G27: 0801179630 | H27: Số nhà 13/75 Bùi Thị Xuân, Phường Lê Thanh Nghị, TP Hải Phòng, Việt Nam. | I27: ’01675599541 | J27: NGUYỄN VĂN VĨNH | K27: NGUYEN VAN VINH | L27: GIÁM ĐỐC | M27: 总经理 | N27: Số nhà 13/75 Bùi Thị Xuân, Phường Lê Thanh Nghị, Thành phố Hải Dương, Tỉnh Hải Dương, Việt Nam | W27: =B27 -> 2141120020 | AA27: 郑明黄 | AD27: 越南海防市黎青议坊裴氏春路13/75号门牌 | AF27: 订单生效之日起3个工作日内，乙方应支付订单金额的【50】%作为预付款；自产品到达越南目的港/站后3个工作日内，乙方应支付订单金额剩余的全部款项。甲方将在收到订单100%款项后送货到乙方指定的收货地点。 Trong vòng 03 ngày làm việc kể từ ngày đơn hàng có hiệu lực, Bên Mua phải thanh toán 【50】% giá trị đơn hàng dưới hình thức tiền tạm ứng; trong vòng 03 ngày làm việc kể từ ngày sản phẩm đến cảng/ga đích tại Việt Nam, Bên Mua phải thanh toán toàn bộ số tiền còn lại của đơn hàng. Bên Bán sẽ giao hàng đến địa điểm nhận hàng do Bên Mua chỉ định sau khi nhận được 100% giá trị thanh toán của đơn hàng. | AG27: =VLOOKUP(B27,'[1]Danh sách khách hàng'!$B:$G,6,FALSE) -> Số nhà 13/75 Bùi Thị Xuân, Phường Lê Thanh Nghị, TP Hải Phòng, Việt Nam.
A28: 27 | B28: 2141120010 | C28: 越南KEKI股份有限公司（工业） | D28: CÔNG TY CỔ PHẦN KEKI VIỆT NAM | G28: 0801249246 | H28: Thửa đất số 1488, tờ bản đồ số 09, Xã Thanh Miện, TP Hải Phòng, Việt Nam. | I28: 369691298 | J28: Ông Phạm Hữu Tuấn | K28: 范友俊 | L28: Tổng giám đốc | M28: 总经理 | N28: Thửa đất số 1488, tờ bản đồ số 09, Thị Trấn Thanh Miện, Huyện Thanh Miện, Tỉnh Hải Dương, Việt Nam | W28: =B28 -> 2141120010 | X28: Ngân hàng BIDV CN Hải Dương | Y28: 越南投资发展银行海阳支行 | Z28: 4603396905 | AA28: 郑明黄 | AD28: 越南海防市青沔乡第09号地图块1488号地块 | AF28: 订单采用【定金30%】的方式。乙方应自订单生效之日起10个工作日内（以甲方所在地时间为准）将【付定金30%】和在通知到货后付清剩余的70%货款以【电汇】方式支付至甲方指定账户，并以邮件或即时通讯软件的方式提供有效的支付凭证，由此产生的转账费用（包括但不限于中转行手续费）由乙方承担。甲方将在收到足额货款或支付凭证后安排生产、检验检疫及进出口手续。 Đơn đặt hàng theo phương thức thanh toán 【đặt cọc 30%】. Trong vòng 10 ngày làm việc kể từ ngày đơn đặt hàng có hiệu lực (giờ địa phương của Bên A), Bên B cần thanh toán 【đặt cọc 30%】 và thanh toán hết 70% phần còn lại sau khi có thông báo hàng đến bằng 【Chuyển khoản điện tử】 vào tài khoản do Bên A chỉ định và cung cấp chứng từ thanh toán hợp lệ qua email hoặc tin nhắn. Bất kỳ khoản phí chuyển khoản nào phát sinh (bao gồm nhưng không giới hạn ở phí ngân hàng trung chuyển) sẽ do Bên B chịu. Bên A sẽ thu xếp các thủ tục sản xuất, kiểm tra, kiểm dịch và xuất nhập khẩu sau khi nhận đủ tiền thanh toán hoặc chứng từ thanh toán. | AG28: =VLOOKUP(B28,'[1]Danh sách khách hàng'!$B:$G,6,FALSE) -> Thửa đất số 1488, tờ bản đồ số 09, Xã Thanh Miện, TP Hải Phòng, Việt Nam.
A29: 28 | B29: 2141130010 | C29: 越南流行水族有限公司 | D29: CÔNG TY TNHH POP AQUA | E29: CONG TY TNHH POP AQUA | F29: 北江 | G29: 2400944895 | H29: Số nhà 17, Tổ dân phố số 3, Phường Đa Mai, Bắc Ninh, Việt Nam. | I29: 0326296668 | J29: LUONG VAN LOC | K29: LUONG VAN LOC | L29: Tổng giám đốc | M29: 总经理 | N29: Số nhà 17, tổ dân phố số 3, phường Mỹ Độ, thành phố Bắc Giang, tỉnh Bắc Giang | O29: LƯƠNG VĂN LỘC | P29: 0326296668 - 0373826710 | V29: pop.aquarium.sp@gmail.com | W29: =B29 -> 2141130010 | X29: Ngân hàng VietinBank - Bắc Giang | Y29: 越南工商银行北江分行​ | Z29: 119002923696 | AA29: 阮文忠 | AD29: 越南北宁省多梅坊第3居民组17号门牌 | AF29: 订单生效之日起3个工作日内，乙方应支付订单金额的【50】%作为预付款；自产品到达越南目的港/站后3个工作日内，乙方应支付订单金额剩余的全部款项。甲方将在收到订单100%款项后送货到乙方指定的收货地点。 Trong vòng 03 ngày làm việc kể từ ngày đơn hàng có hiệu lực, Bên Mua phải thanh toán 【50】% giá trị đơn hàng dưới hình thức tiền tạm ứng; trong vòng 03 ngày làm việc kể từ ngày sản phẩm đến cảng/ga đích tại Việt Nam, Bên Mua phải thanh toán toàn bộ số tiền còn lại của đơn hàng. Bên Bán sẽ giao hàng đến địa điểm nhận hàng do Bên Mua chỉ định sau khi nhận được 100% giá trị thanh toán của đơn hàng. | AG29: =VLOOKUP(B29,'[1]Danh sách khách hàng'!$B:$G,6,FALSE) -> Số nhà 17, Tổ dân phố số 3, Phường Đa Mai, Bắc Ninh, Việt Nam.
A30: 29 | B30: 2141020190 | C30: 越南亚洲化学股份有限公司（工业） | D30: CÔNG TY CỔ PHẦN HÓA CHẤT Á CHÂU | E30: CONG TY CO PHAN HOA CHAT A CHAU | F30: ACC | G30: 0304918352 | H30: Lô K4B khu công nghiệp Lê Minh Xuân, Đường Số 4, Xã Bình Lợi, TP Hồ Chí Minh, Việt Nam. | I30: 0838868174 | J30: PHAN DUY HIEU | K30: PHAN DUY HIEU | L30: Tổng giám đốc | M30: 总经理 | N30: 12 đại lộ độc lập , khu công nghiệp sóng thần 1 , dĩ an, dĩ an bình dương | P30: Anh Nhân - Thủ kho: 0938939817 | V30: info@asia-chemical.com | W30: =B30 -> 2141020190 | X30: Vietinbank Chi nhánh 7 - thành phố Hồ Chí Minh | Y30: ​​越南工商银行胡志明市​第七分行 | Z30: 117002653125 | AA30: 彭烨 | AD30: 越南胡志明市平利乡4号路黎明春工业区K4B地块 | AF30: 买方（乙方）须在签订采购订单后立即支付订单总金额的 50%，剩余的 50% 款项必须在收货前（卖方交货前）全部付清。买方付款后，须通过电子邮件或在线聊天软件向卖方提供有效的付款凭证；卖方只有在收到足额款项或有效付款凭证后，才会安排生产、检验、检疫及进出口手续。同时，任何因转账产生的费用（包括但不限于中转行费用）均由买方（乙方）承担。 Bên B thanh toán cho Bên A trước 50% tổng giá trị đơn hàng ngay khi ký Đơn đặt hàng, và 50% còn lại thanh toán hết trước khi nhận hàng (trước khi Bên A giao hàng). Sau khi chuyển khoản, Bên B cần cung cấp chứng từ thanh toán hợp lệ qua email hoặc ứng dụng trò chuyện trực tuyến; Bên A chỉ sắp xếp các thủ tục sản xuất, kiểm tra, kiểm dịch, xuất nhập khẩu sau khi nhận đủ số tiền hoặc chứng từ thanh toán này. Đồng thời, bất kỳ khoản phí chuyển khoản nào phát sinh (bao gồm nhưng không giới hạn ở phí ngân hàng trung chuyển) sẽ hoàn toàn do Bên B chịu. | AG30: =VLOOKUP(B30,'[1]Danh sách khách hàng'!$B:$G,6,FALSE) -> Lô K4B khu công nghiệp Lê Minh Xuân, Đường Số 4, Xã Bình Lợi, TP Hồ Chí Minh, Việt Nam.
A31: 30 | B31: 2141010120 | C31: 越南美越食品供应有限公司 | D31: CÔNG TY TNHH CUNG CẤP THỰC PHẨM MỸ VIỆT | E31: CONG TY TNHH CUNG CAP THUC PHAM MY VIET | F31: 美越 | G31: 0110189527 | H31: Kiot 19-20-21 Tòa CT9 Khu đô thị Định Công, Phường Phương Liệt, TP Hà Nội, Việt Nam. | I31: 0899803689 | J31: BA DANG THU ANH | K31: BA DANG THU ANH | L31: Tổng giám đốc | M31: 总经理 | V31: pptpvietmy@gmail.com | W31: =B31 -> 2141010120 | X31: MB Bank CN Hai Bà Trưng | Y31: 越南军队商业银行二征夫人区分行 | Z31: 2689368999 | AA31: 郑明黄 | AD31: 越南河内市芳烈坊定功新市区CT9大楼19-20-21号商铺 | AF31: 订单生效之日起3个工作日内，乙方应支付订单金额的【50】%作为预付款；自产品到达越南目的港/站后3个工作日内，乙方应支付订单金额剩余的全部款项。甲方将在收到订单100%款项后送货到乙方指定的收货地点。 Trong vòng 03 ngày làm việc kể từ ngày đơn hàng có hiệu lực, Bên Mua phải thanh toán 【50】% giá trị đơn hàng dưới hình thức tiền tạm ứng; trong vòng 03 ngày làm việc kể từ ngày sản phẩm đến cảng/ga đích tại Việt Nam, Bên Mua phải thanh toán toàn bộ số tiền còn lại của đơn hàng. Bên Bán sẽ giao hàng đến địa điểm nhận hàng do Bên Mua chỉ định sau khi nhận được 100% giá trị thanh toán của đơn hàng. | AG31: =VLOOKUP(B31,'[1]Danh sách khách hàng'!$B:$G,6,FALSE) -> Kiot 19-20-21 Tòa CT9 Khu đô thị Định Công, Phường Phương Liệt, TP Hà Nội, Việt Nam.
A32: 31 | B32: 2141010130 | C32: 越南山水发商贸服务股份公司 | D32: CÔNG TY CỔ PHẦN THƯƠNG MẠI VÀ DỊCH VỤ SƠN THỦY PHÁT | E32: CONG TY CO PHAN THUONG MAI VA DICH VU SON THUY PHAT | F32: 山水发 | G32: 0105021487 | H32: Số 7, hẻm 823/19/2 đường Hồng Hà, Phường Hồng Hà, TP Hà Nội, Việt Nam. | I32: 0912961292 | J32: VU THI THUY | K32: VU THI THUY | L32: Tổng giám đốc | M32: 总经理 | V32: sonthuyphat@gmail.com | W32: =B32 -> 2141010130 | X32: Ngân hàng á Châu ACB - chi nhánh Nguyễn Thị Định | Y32: 亚洲商业银行阮氏定区分行​ | Z32: 195695889 | AA32: 郑明黄 | AD32: 越南河内市红河坊红河路823/19/2号巷7号 | AF32: 订单生效之日起3个工作日内，乙方应支付订单金额的【50】%作为预付款；自产品到达越南目的港/站后3个工作日内，乙方应支付订单金额剩余的全部款项。甲方将在收到订单100%款项后送货到乙方指定的收货地点。 Trong vòng 03 ngày làm việc kể từ ngày đơn hàng có hiệu lực, Bên Mua phải thanh toán 【50】% giá trị đơn hàng dưới hình thức tiền tạm ứng; trong vòng 03 ngày làm việc kể từ ngày sản phẩm đến cảng/ga đích tại Việt Nam, Bên Mua phải thanh toán toàn bộ số tiền còn lại của đơn hàng. Bên Bán sẽ giao hàng đến địa điểm nhận hàng do Bên Mua chỉ định sau khi nhận được 100% giá trị thanh toán của đơn hàng. | AG32: =VLOOKUP(B32,'[1]Danh sách khách hàng'!$B:$G,6,FALSE) -> Số 7, hẻm 823/19/2 đường Hồng Hà, Phường Hồng Hà, TP Hà Nội, Việt Nam.
A33: 32 | B33: 2141140010 | C33: 越南秋香贸易经营有限责任公司​ | D33: CÔNG TY TNHH KINH DOANH THƯƠNG MẠI THU HƯƠNG | E33: CONG TY TNHH KINH DOANH THUONG MAI THU HUONG | F33: 秋香 | G33: 0601287156 | H33: Số 16 đường Hưng Yên, Phường Nam Định, Ninh Bình, Việt Nam. | I33: 0913344477 | J33: DINH THI THU HUONG | K33: DINH THI THU HUONG | L33: Tổng giám đốc | M33: 总经理 | V33: thuhuong.trading@gmail.com | W33: =B33 -> 2141140010 | X33: Ngân hàng á Châu ACB - chi nhánh tỉnh Nam Định | Y33: 亚洲商业银行 南定省分行​ | Z33: 2366856 | AA33: 郑明黄 | AD33: 越南宁平省南定坊兴安路16号 | AF33: 订单生效之日起3个工作日内，乙方应支付订单金额的【50】%作为预付款；自产品到达越南目的港/站后3个工作日内，乙方应支付订单金额剩余的全部款项。甲方将在收到订单100%款项后送货到乙方指定的收货地点。 Trong vòng 03 ngày làm việc kể từ ngày đơn hàng có hiệu lực, Bên Mua phải thanh toán 【50】% giá trị đơn hàng dưới hình thức tiền tạm ứng; trong vòng 03 ngày làm việc kể từ ngày sản phẩm đến cảng/ga đích tại Việt Nam, Bên Mua phải thanh toán toàn bộ số tiền còn lại của đơn hàng. Bên Bán sẽ giao hàng đến địa điểm nhận hàng do Bên Mua chỉ định sau khi nhận được 100% giá trị thanh toán của đơn hàng. | AG33: =VLOOKUP(B33,'[1]Danh sách khách hàng'!$B:$G,6,FALSE) -> Số 16 đường Hưng Yên, Phường Nam Định, Ninh Bình, Việt Nam.
A34: 33 | B34: 2141160010 | C34: 越南泰东兴有限公司 | D34: CÔNG TY TNHH THÁI ĐÔNG HƯNG | E34: CONG TY TNHH THAI DONG HUNG | F34: 泰东兴 | G34: 0401493641 | H34: 130 Phạm Đình Hổ, Phường Thanh Khê, TP Đà Nẵng, Việt Nam. | I34: 0982156159 | J34: Đinh Ngọc Dinh | K34: 丁玉圣 | L34: Tổng giám đốc | M34: 总经理 | N34: 172-178 Bùi Tấn Diên, phường Hòa Khánh, thành phố Đà Nẵng, Việt Nam | O34: Đinh Ngọc Dinh | P34: 0932159830 | V34: dinhcaor@gmail.com | W34: =B34 -> 2141160010 | X34: Ngân hàng Nông nghiệp và Phát triển Nông thôn Việt Nam - Chi nhánh Thanh Khê Đà Nẵng - phòng giao dịch Thanh Lộc Đán | Y34: 越南农业与农村发展银行 - 岘港市清溪区清禄旦营业点 | Z34: 2003201085786 | AA34: 朱建君 | AD34: 越南岘港市清溪郡范廷琥路130号 | AF34: 订单生效之日起3个工作日内，乙方应支付订单金额的【50】%作为预付款；自产品到达越南目的港/站后3个工作日内，乙方应支付订单金额剩余的全部款项。甲方将在收到订单100%款项后送货到乙方指定的收货地点。 Trong vòng 03 ngày làm việc kể từ ngày đơn hàng có hiệu lực, Bên Mua phải thanh toán 【50】% giá trị đơn hàng dưới hình thức tiền tạm ứng; trong vòng 03 ngày làm việc kể từ ngày sản phẩm đến cảng/ga đích tại Việt Nam, Bên Mua phải thanh toán toàn bộ số tiền còn lại của đơn hàng. Bên Bán sẽ giao hàng đến địa điểm nhận hàng do Bên Mua chỉ định sau khi nhận được 100% giá trị thanh toán của đơn hàng. | AG34: =VLOOKUP(B34,'[1]Danh sách khách hàng'!$B:$G,6,FALSE) -> 130 Phạm Đình Hổ, Phường Thanh Khê, TP Đà Nẵng, Việt Nam.
A35: 34 | B35: 2141170010 | C35: 越南宝芳林有限责任公司 | D35: CÔNG TY TNHH BẢO PHƯƠNG LÂM | E35: CONG TY TNHH BAO PHUONG LAM | F35: 宝芳林 | G35: '0111304719 | H35: NO13-LK13-04, Khu đất dịch vụ LK8, LK9, LK10, LK15, LK21, LK23, LK24, LK26, C6, TH17 đường Nguyễn Thanh Bình, Phường Hà Đông, TP Hà Nội, Việt Nam. | I35: 0765526888 | J35: TRẦN THỊ NGỌC ANH | K35: TRAN THI NGOC ANH | L35: Tổng giám đốc | M35: 总经理 | N35: NO13-LK13-04, Khu đất dịch vụ LK8, LK9, LK10, LK15, LK21, LK23, LK24, LK26, C6, TH17 đường Nguyễn Thanh Bình, Phường Hà Đông, TP Hà Nội, Việt Nam | O35: TRẦN THỊ NGỌC ANH | P35: '0765526888 | V35: ngocanhtran17081993@gmail.com | W35: =B35 -> 2141170010 | X35: Ngân hàng Techcombank - Chi nhánh Ba Đình | Y35: 越南科技商业银行巴亭分行 | Z35: 65526888 | AA35: 阮文忠 | AD35: 越南河内市河东郡阮青平路，LK8、LK9、LK10、LK15、LK21、LK23、LK24、LK26、C6、TH17服务用地地块NO13-LK13-04号 (文本右侧被截断) | AF35: 订单生效之日起3个工作日内，乙方应支付订单金额的【50】%作为预付款；自产品到达越南目的港/站后3个工作日内，乙方应支付订单金额剩余的全部款项。甲方将在收到订单100%款项后送货到乙方指定的收货地点。 Trong vòng 03 ngày làm việc kể từ ngày đơn hàng có hiệu lực, Bên Mua phải thanh toán 【50】% giá trị đơn hàng dưới hình thức tiền tạm ứng; trong vòng 03 ngày làm việc kể từ ngày sản phẩm đến cảng/ga đích tại Việt Nam, Bên Mua phải thanh toán toàn bộ số tiền còn lại của đơn hàng. Bên Bán sẽ giao hàng đến địa điểm nhận hàng do Bên Mua chỉ định sau khi nhận được 100% giá trị thanh toán của đơn hàng. | AG35: =VLOOKUP(B35,'[1]Danh sách khách hàng'!$B:$G,6,FALSE) -> NO13-LK13-04, Khu đất dịch vụ LK8, LK9, LK10, LK15, LK21, LK23, LK24, LK26, C6, TH17 đường Nguyễn Thanh Bình, Phường Hà Đông, TP Hà Nội, Việt Nam.
A36: 35 | B36: 2141190020 | C36: 越南卷芝贸易服务有限公司 | D36: CÔNG TY TNHH THƯƠNG MẠI VÀ DỊCH VỤ QUYẾN CHI | E36: CONG TY TNHH THUONG MAI VA DICH VU QUYEN CHI | F36: 北宁 | G36: 2301335973 | H36: Xóm Già A, Khu 3, Phường Vũ Ninh, Bắc Ninh, Việt Nam. | I36: 0387882186 | J36: VŨ XUÂN QUYẾN | K36: VŨ XUÂN QUYẾN | L36: GIÁM ĐỐC | M36: 总经理 | N36: Số 9 Trần Đăng Tuyển ,Vũ Ninh , Bắc Ninh | O36: VŨ XUÂN QUYẾN | P36: 387882186 | V36: quyenchi7783@gmail.com | W36: =B36 -> 2141190020 | X36: VIETNAM JOINT STOCK COMMERCIAL BANK FOR INDUSTRY AND TRADE (VIETIN BANK) | Y36: 越南工商银行 | Z36: 21228383 | AA36: 阮文忠 | AD36: 越南北宁省武宁坊第3区老A村 | AF36: 订单生效之日起3个工作日内，乙方应支付订单金额的【50】%作为预付款；自产品到达越南目的港/站后3个工作日内，乙方应支付订单金额剩余的全部款项。甲方将在收到订单100%款项后送货到乙方指定的收货地点。 Trong vòng 03 ngày làm việc kể từ ngày đơn hàng có hiệu lực, Bên Mua phải thanh toán 【50】% giá trị đơn hàng dưới hình thức tiền tạm ứng; trong vòng 03 ngày làm việc kể từ ngày sản phẩm đến cảng/ga đích tại Việt Nam, Bên Mua phải thanh toán toàn bộ số tiền còn lại của đơn hàng. Bên Bán sẽ giao hàng đến địa điểm nhận hàng do Bên Mua chỉ định sau khi nhận được 100% giá trị thanh toán của đơn hàng. | AG36: =VLOOKUP(B36,'[1]Danh sách khách hàng'!$B:$G,6,FALSE) -> Xóm Già A, Khu 3, Phường Vũ Ninh, Bắc Ninh, Việt Nam.
A37: 36 | B37: 2141190010 | C37: 越南福禄BG进出口有限公司 | D37: CONG TY TNHH XNK PHUC LOC BG | E37: CONG TY TNHH XNK PHUC LOC BG | F37: 北江 | G37: 2401061878 | H37: Đường Nguyễn Thái Học, Tổ Dân Phố Xóm Ba, Phường Đa Mai, Bắc Ninh, Việt Nam. | I37: 0983915597 | J37: LƯƠNG VĂN PHÚC | K37: LƯƠNG VĂN PHÚC | L37: GIÁM ĐỐC | M37: 总经理 | N37: Tổ 3 phường đa mai tỉnh bắc ninh | O37: LƯƠNG VĂN LỘC | P37: 0326296668 - 0373826710 | V37: locbgphuc@gmail.com | W37: =B37 -> 2141190010 | X37: VIETNAM JOINT STOCK COMMERCIAL BANK FOR INDUSTRY AND TRADE (VIETIN BANK) | Y37: 越南工商银行 | Z37: 110646848886 | AA37: 阮文忠 | AD37: 越南北宁省多梅坊三村居民组阮太学路 | AF37: 订单生效之日起3个工作日内，乙方应支付订单金额的【50】%作为预付款；自产品到达越南目的港/站后3个工作日内，乙方应支付订单金额剩余的全部款项。甲方将在收到订单100%款项后送货到乙方指定的收货地点。 Trong vòng 03 ngày làm việc kể từ ngày đơn hàng có hiệu lực, Bên Mua phải thanh toán 【50】% giá trị đơn hàng dưới hình thức tiền tạm ứng; trong vòng 03 ngày làm việc kể từ ngày sản phẩm đến cảng/ga đích tại Việt Nam, Bên Mua phải thanh toán toàn bộ số tiền còn lại của đơn hàng. Bên Bán sẽ giao hàng đến địa điểm nhận hàng do Bên Mua chỉ định sau khi nhận được 100% giá trị thanh toán của đơn hàng. | AG37: =VLOOKUP(B37,'[1]Danh sách khách hàng'!$B:$G,6,FALSE) -> Đường Nguyễn Thái Học, Tổ Dân Phố Xóm Ba, Phường Đa Mai, Bắc Ninh, Việt Nam.
A38: 37 | B38: 2141290010 | C38: 越南鸿发MC进出口有限公司 | D38: CÔNG TY TNHH XUẤT NHẬP KHÂU HOÀN PHÁT MC | E38: CONG TY TNHH XUAT NHAP KHAU HOAN PHAT MC | F38: 芒街 | G38: 5702163540 | H38: SN B11, S17 Khu Đô Thị Phượng Hoàng, Thôn 13, Phường Móng Cái 1, Quảng Ninh, Việt Nam. | I38: 0913237269 | J38: NGUYỄN XUÂN HOÀN | K38: NGUYỄN XUÂN HOÀN | L38: GIÁM ĐỐC | M38: 总经理 | N38: Ngã 5 ninh dương , cảng quang phát 1 , phường mc 2 | O38: NGUYỄN XUÂN HOÀN | P38: 913237269 | V38: tamtithxmc@gmail.com | W38: =B38 -> 2141290010 | X38: AGRIBANK PLC | Y38: 农业银行 | Z38: 8090666663999 | AA38: 阮文忠 | AD38: 越南广宁省芒街1坊13村凤皇新市区B11, S17号门牌 | AF38: 订单生效之日起3个工作日内，乙方应支付订单金额的【50】%作为预付款；自产品到达越南目的港/站后3个工作日内，乙方应支付订单金额剩余的全部款项。甲方将在收到订单100%款项后送货到乙方指定的收货地点。 Trong vòng 03 ngày làm việc kể từ ngày đơn hàng có hiệu lực, Bên Mua phải thanh toán 【50】% giá trị đơn hàng dưới hình thức tiền tạm ứng; trong vòng 03 ngày làm việc kể từ ngày sản phẩm đến cảng/ga đích tại Việt Nam, Bên Mua phải thanh toán toàn bộ số tiền còn lại của đơn hàng. Bên Bán sẽ giao hàng đến địa điểm nhận hàng do Bên Mua chỉ định sau khi nhận được 100% giá trị thanh toán của đơn hàng. | AG38: =VLOOKUP(B38,'[1]Danh sách khách hàng'!$B:$G,6,FALSE) -> SN B11, S17 Khu Đô Thị Phượng Hoàng, Thôn 13, Phường Móng Cái 1, Quảng Ninh, Việt Nam.
A39: 38 | B39: 2141040020 | C39: 越南明缘进出口有限公司 | D39: CÔNG TY TNHH XUẤT NHẬP KHẨU MINH DUYÊN | E39: CONG TY TNHH XUAT NHAP KHAU MINH DUYEN | F39: 老街 | G39: 5300836228 | H39: Số nhà 073, Thôn Hồng Giang, Phường Lào Cai, Lào Cai, Việt Nam. | I39: 0868251224 | J39: ĐẢO ĐỨC MINH | K39: ĐẢO ĐỨC MINH | L39: GIÁM ĐỐC | M39: 总经理 | N39: Kho lưu bằng, kcn bắc duyên hải, tp lào cai tỉnh lào cai | O39: ĐẢO ĐỨC MINH | P39: 868251224 | V39: xnkminhduyenlc@gmail.com | W39: =B39 -> 2141040020 | X39: MILITARY COMMERCIAL JOINT STOCK BANK | Y39: 越南军队商业银行 | Z39: 5300836228 | AA39: 阮文忠 | AD39: 越南老街省老街坊红江村073号门牌 | AF39: 订单生效之日起3个工作日内，乙方应支付订单金额的【50】%作为预付款；自产品到达越南目的港/站后3个工作日内，乙方应支付订单金额剩余的全部款项。甲方将在收到订单100%款项后送货到乙方指定的收货地点。 Trong vòng 03 ngày làm việc kể từ ngày đơn hàng có hiệu lực, Bên Mua phải thanh toán 【50】% giá trị đơn hàng dưới hình thức tiền tạm ứng; trong vòng 03 ngày làm việc kể từ ngày sản phẩm đến cảng/ga đích tại Việt Nam, Bên Mua phải thanh toán toàn bộ số tiền còn lại của đơn hàng. Bên Bán sẽ giao hàng đến địa điểm nhận hàng do Bên Mua chỉ định sau khi nhận được 100% giá trị thanh toán của đơn hàng. | AG39: =VLOOKUP(B39,'[1]Danh sách khách hàng'!$B:$G,6,FALSE) -> Số nhà 073, Thôn Hồng Giang, Phường Lào Cai, Lào Cai, Việt Nam.
A40: 39 | B40: 2141020200 | C40: 越南国宴云厨房有限公司（工业） | D40: CONG TY TNHH QUỐC YẾN CLOUD KITCHEN | E40: CONG TY TNHH QUOC YEN CLOUD KITCHEN | F40: 国宴 | G40: 0309576416 | H40: 3SB1-12 Đường số 20, Khu phố Mỹ Viên, Khu đô thị Phú Mỹ Hưng, Phường Tân Mỹ, Thành phố Hồ Chí Minh, Việt Nam | I40: 0888058989 | J40: LÝ TRƯƠNG HUY | K40: 黎长辉 | L40: Chủ tịch Công ty | M40: 公司主席 | W40: =B40 -> 2141020200 | X40: Ngân Hàng Agribank | Y40: 越南农业与农村发展银行 | Z40: 6240238000389 | AD40: 越南胡志明市新富坊富美兴新城美缘小区20号路3SB1-12 | AF40: 订单生效之日起3个工作日内，乙方应支付订单金额的【50】%作为预付款；自产品到达越南目的港/站后3个工作日内，乙方应支付订单金额剩余的全部款项。甲方将在收到订单100%款项后送货到乙方指定的收货地点。 Trong vòng 03 ngày làm việc kể từ ngày đơn hàng có hiệu lực, Bên Mua phải thanh toán 【50】% giá trị đơn hàng dưới hình thức tiền tạm ứng; trong vòng 03 ngày làm việc kể từ ngày sản phẩm đến cảng/ga đích tại Việt Nam, Bên Mua phải thanh toán toàn bộ số tiền còn lại của đơn hàng. Bên Bán sẽ giao hàng đến địa điểm nhận hàng do Bên Mua chỉ định sau khi nhận được 100% giá trị thanh toán của đơn hàng.
...

Sheet 三品订单
C1: 三品清单 | D1: 如遇三品缺货，直接取消发该三品，不作换货沟通，请知悉
B2: 序号 | C2: 物料编码 | D2: 物料描述 | E2: 统一售价 (CNY) | F2: 单位 | G2: 毛重 | H2: 体积(M3) | I2: 包装尺寸 | J2: 数量 | K2: 总毛重(KG) | L2: 总体积(M3)
A3: =IFERROR(RANK(J3,$J$3:$J$23,1)+COUNTIFS(J$3:J3,J3)-1,"") | B3: 1 | C3: 41005059 | D3: 海天白色味碟（2个/盒，60盒/箱） | E3: 267.35 | F3: 箱 | G3: 13 | H3: 0.02559375 | I3: 35*32.5*22.5cm | K3: =J3*G3 -> 0 | L3: =H3*J3 -> 0
A4: =IFERROR(RANK(J4,$J$3:$J$23,1)+COUNTIFS(J$3:J4,J4)-1,"") | B4: 2 | C4: 41005175 | D4: 自动开合桌上瓶（箱，48盒/箱） | E4: 231.84 | F4: 箱 | G4: 10.5 | H4: 0.036366 | I4: 44*29*28.5cm | K4: =J4*G4 -> 0 | L4: =H4*J4 -> 0
A5: =IFERROR(RANK(J5,$J$3:$J$23,1)+COUNTIFS(J$3:J5,J5)-1,"") | B5: 3 | C5: 41005116 | D5: 能抗菌的洗洁布（200包/箱） | E5: 239.4 | F5: 箱 | G5: 8.1 | H5: 0.05928 | I5: 65*32*28.5cm | K5: =J5*G5 -> 0 | L5: =H5*J5 -> 0
A6: =IFERROR(RANK(J6,$J$3:$J$23,1)+COUNTIFS(J$3:J6,J6)-1,"") | B6: 4 | C6: 41004086 | D6: 味极鲜覆膜环保购物袋（50个/扎） | E6: 48.83 | F6: 扎 | G6: 2.4 | H6: 0.020475 | I6: 35*39*15cm | K6: =J6*G6 -> 0 | L6: =H6*J6 -> 0
A7: =IFERROR(RANK(J7,$J$3:$J$23,1)+COUNTIFS(J$3:J7,J7)-1,"") | B7: 5 | C7: 41004119 | D7: 黄豆酱覆膜环保购物袋（50个/扎） | E7: 48.83 | F7: 扎 | G7: 2.34 | H7: 0.01296 | I7: 30*24*18cm | K7: =J7*G7 -> 0 | L7: =H7*J7 -> 0
A8: =IFERROR(RANK(J8,$J$3:$J$23,1)+COUNTIFS(J$3:J8,J8)-1,"") | B8: 6 | C8: 41004134 | D8: 海天福字购物袋（50个/扎） | E8: 48.83 | F8: 扎 | G8: 2.34 | H8: 0.018081 | I8: 42*41*10.5cm | K8: =J8*G8 -> 0 | L8: =H8*J8 -> 0
A9: =IFERROR(RANK(J9,$J$3:$J$23,1)+COUNTIFS(J$3:J9,J9)-1,"") | B9: 7 | C9: 41004752 | D9: 出口版海天覆膜环保购物袋（扎，50个/扎） | E9: 48.83 | F9: 扎 | G9: 2.34 | H9: 0.018081 | I9: 42*41*10.5cm | K9: =J9*G9 -> 0 | L9: =H9*J9 -> 0
A10: =IFERROR(RANK(J10,$J$3:$J$23,1)+COUNTIFS(J$3:J10,J10)-1,"") | B10: 8 | C10: 41003010 | D10: 品牌帐篷（1套/箱） | E10: 225.72 | F10: 箱 | G10: 20.5 | H10: 0.0588 | I10: 147*20*20cm | K10: =J10*G10 -> 0 | L10: =H10*J10 -> 0
A11: =IFERROR(RANK(J11,$J$3:$J$23,1)+COUNTIFS(J$3:J11,J11)-1,"") | B11: 9 | C11: 41003071 | D11: 酱油版大包装陈列架简易版（1套/箱） | E11: 302.4 | F11: 箱 | G11: 21.57 | H11: 0.1296 | I11: 96*75*18cm | K11: =J11*G11 -> 0 | L11: =H11*J11 -> 0
A12: =IFERROR(RANK(J12,$J$3:$J$23,1)+COUNTIFS(J$3:J12,J12)-1,"") | B12: 10 | C12: 41003072 | D12: 蚝油版大包装陈列架简易版（1套/箱） | E12: 302.4 | F12: 箱 | G12: 21.57 | H12: 0.1296 | I12: 96*75*18cm | K12: =J12*G12 -> 0 | L12: =H12*J12 -> 0
A13: =IFERROR(RANK(J13,$J$3:$J$23,1)+COUNTIFS(J$3:J13,J13)-1,"") | B13: 11 | C13: 41003070 | D13: 海天阳光小店陈列架简易版（1套/箱） | E13: 199.8 | F13: 箱 | G13: 15.95 | H13: 0.079 | I13: 81*61*16cm | K13: =J13*G13 -> 0 | L13: =H13*J13 -> 0
A14: =IFERROR(RANK(J14,$J$3:$J$23,1)+COUNTIFS(J$3:J14,J14)-1,"") | B14: 12 | C14: 41002036 | D14: 大包装价格贴（200张/包） | E14: 19.55 | F14: 包 | G14: 1.241 | H14: 0.001 | I14: 18.5*17.2*0.1cm | K14: =J14*G14 -> 0 | L14: =H14*J14 -> 0
... A24: =IFERROR(RANK(J24,$J$3:$J$23,1)+COUNTIFS(J$3:J24,J24)-1,"") | B24: 22 | C24: 41003081 | D24: 2024年小台历礼盒（箱，10盒/箱） | E24: 239 | F24: 箱 | G24: 12 | H24: 0.005 | I24: 28*28*6cm | K24: =J24*G24 -> 0 | L24: =H24*J24 -> 0
B25: TOTAL | J25: =SUM(J3:J24) -> 0 | K25: =SUM(K3:K24) -> 0 | L25: =SUM(L3:L24) -> 0

Sheet 越南文大写金额计算
A1: Hàm chuyển số thành chữ | C1: =#REF! -> #REF! | G1: Nhập số vào đây
B2: =C1+10^12 -> #REF! | C2: 1 | D2: 2 | E2: 3 | F2: 4 | G2: 5 | H2: 6 | I2: 7 | J2: 8 | K2: 9 | L2: 10 | M2: 11 | N2: 12
A3: Tách từng vị trí | C3: =VALUE(MID(B2,C2+1,1)) -> #REF! | D3: =VALUE(MID(B2,D2+1,1)) -> #REF! | E3: =VALUE(MID(B2,E2+1,1)) -> #REF! | F3: =VALUE(MID(B2,F2+1,1)) -> #REF! | G3: =VALUE(MID(B2,G2+1,1)) -> #REF! | H3: =VALUE(MID(B2,H2+1,1)) -> #REF! | I3: =VALUE(MID(B2,I2+1,1)) -> #REF! | J3: =VALUE(MID(B2,J2+1,1)) -> #REF! | K3: =VALUE(MID(B2,K2+1,1)) -> #REF! | L3: =VALUE(MID(B2,L2+1,1)) -> #REF! | M3: =VALUE(MID(B2,M2+1,1)) -> #REF! | N3: =VALUE(MID(B2,N2+1,1)) -> #REF!
A4: Chọn đơn vị | D4: linh | E4: tỷ | G4: linh | H4: triệu | J4: linh | K4: ngàn | M4: lẻ | N4: đồng
A5: Đọc ra chữ | C5: =IF(C3=0,"",CHOOSE(C3,"một","hai","ba","bốn","năm","sáu","bảy","tám","chín")&" trăm") -> #REF! | D5: =IF(SUM(C3:D3)=0,"",IF(AND(D3=0,E3=0),"",IF(AND(D3=0,E3<>0),D4,CHOOSE(D3,"mười","hai mươi","ba mươi","bốn mươi","năm mươi","sáu mươi","bảy mươi","tám mươi","chín mươi")))) -> #REF! | E5: =IF(SUM(C3:E3)=0,"",IF(AND(SUM(C3:D3)>0,E3=0)," "&E4,CHOOSE(E3,IF(D3>0,"mốt","một"),"hai","ba","bốn",IF(D3>0,"lăm","năm"),"sáu","bảy","tám","chín")&" "&E4)) -> #REF! | F5: =IF(SUM(C3:F3)=0,"",IF(SUM(F3:H3)=0,"",IF(F3=0,"không trăm",CHOOSE(F3,"một","hai","ba","bốn","năm","sáu","bảy","tám","chín")&" trăm"))) -> #REF! | G5: =IF(SUM(C3:G3)=0,"",IF(AND(G3=0,H3=0),"",IF(AND(G3=0,H3<>0),G4,CHOOSE(G3,"mười","hai mươi","ba mươi","bốn mươi","năm mươi","sáu mươi","bảy mươi","tám mươi","chín mươi")))) -> #REF! | H5: =IF(SUM(F3:H3)=0,"",IF(AND(SUM(C3:G3)>0,H3=0)," "&H4,CHOOSE(H3,IF(G3>0,"mốt","một"),"hai","ba","bốn",IF(G3>0,"lăm","năm"),"sáu","bảy","tám","chín")&" "&H4)) -> #REF! | I5: =IF(SUM(C3:I3)=0,"",IF(SUM(I3:K3)=0,"",IF(I3=0,"không trăm",CHOOSE(I3,"một","hai","ba","bốn","năm","sáu","bảy","tám","chín")&" trăm"))) -> #REF! | J5: =IF(SUM(C3:J3)=0,"",IF(AND(J3=0,K3=0),"",IF(AND(J3=0,K3<>0),J4,CHOOSE(J3,"mười","hai mươi","ba mươi","bốn mươi","năm mươi","sáu mươi","bảy mươi","tám mươi","chín mươi")))) -> #REF! | K5: =IF(SUM(I3:K3)=0,"",IF(AND(SUM(C3:J3)>0,K3=0)," "&K4,CHOOSE(K3,IF(J3>0,"mốt","một"),"hai","ba","bốn",IF(J3>0,"lăm","năm"),"sáu","bảy","tám","chín")&" "&K4)) -> #REF! | L5: =IF(SUM(C3:L3)=0,"",IF(SUM(L3:N3)=0,"",IF(L3=0,"không trăm",CHOOSE(L3,"một","hai","ba","bốn","năm","sáu","bảy","tám","chín")&" trăm"))) -> #REF! | M5: =IF(SUM(C3:M3)=0,"",IF(AND(M3=0,N3=0),"",IF(AND(M3=0,N3<>0),M4,CHOOSE(M3,"mười","hai mươi","ba mươi","bốn mươi","năm mươi","sáu mươi","bảy mươi","tám mươi","chín mươi")))) -> #REF! | N5: =IF(SUM(C3:N3)=0,"Không "&N4,IF(AND(SUM(C3:K3)>0,SUM(L3:N3)=0)," "&N4&" chẵn",IF(N3=0," "&N4,CHOOSE(N3,IF(M3>0,"mốt","một"),"hai","ba","bốn",IF(M3>0,"lăm","năm"),"sáu","bảy","tám","chín")&" "&N4)))&"./." -> #REF!
A6: Viết hoa chữ cái đầu trong chuỗi | C6: =IF(C5="","",IF(COUNTIF(B5,"")=C2,UPPER(LEFT(C5,1))&RIGHT(C5,LEN(C5)-1),C5)) -> #REF! | D6: =IF(D5="","",IF(COUNTIF(B5:C5,"")=D2,UPPER(LEFT(D5,1))&RIGHT(D5,LEN(D5)-1),D5)) -> #REF! | E6: =IF(E5="","",IF(COUNTIF(B5:D5,"")=E2,UPPER(LEFT(E5,1))&RIGHT(E5,LEN(E5)-1),E5)) -> #REF! | F6: =IF(F5="","",IF(COUNTIF(B5:E5,"")=F2,UPPER(LEFT(F5,1))&RIGHT(F5,LEN(F5)-1),F5)) -> #REF! | G6: =IF(G5="","",IF(COUNTIF(B5:F5,"")=G2,UPPER(LEFT(G5,1))&RIGHT(G5,LEN(G5)-1),G5)) -> #REF! | H6: =IF(H5="","",IF(COUNTIF(B5:G5,"")=H2,UPPER(LEFT(H5,1))&RIGHT(H5,LEN(H5)-1),H5)) -> #REF! | I6: =IF(I5="","",IF(COUNTIF(B5:H5,"")=I2,UPPER(LEFT(I5,1))&RIGHT(I5,LEN(I5)-1),I5)) -> #REF! | J6: =IF(J5="","",IF(COUNTIF(B5:I5,"")=J2,UPPER(LEFT(J5,1))&RIGHT(J5,LEN(J5)-1),J5)) -> #REF! | K6: =IF(K5="","",IF(COUNTIF(B5:J5,"")=K2,UPPER(LEFT(K5,1))&RIGHT(K5,LEN(K5)-1),K5)) -> #REF! | L6: =IF(L5="","",IF(COUNTIF(B5:K5,"")=L2,UPPER(LEFT(L5,1))&RIGHT(L5,LEN(L5)-1),L5)) -> #REF! | M6: =IF(M5="","",IF(COUNTIF(B5:L5,"")=M2,UPPER(LEFT(M5,1))&RIGHT(M5,LEN(M5)-1),M5)) -> #REF! | N6: =IF(N5="","",IF(COUNTIF(B5:M5,"")=N2,UPPER(LEFT(N5,1))&RIGHT(N5,LEN(N5)-1),N5)) -> #REF!
A7: Kết quả: | B7: =TRIM(C6&" "&D6&" "&E6&" "&F6&" "&G6&" "&H6&" "&I6&" "&J6&" "&K6&" "&L6&" "&M6&" "&N6) -> #REF!

Sheet 付款条款参考
A1: ”付款方式”条款模板
A2: 先款后货 | C2: 自买方同意本确认书之日起3个工作日内，买方应以电汇方式向卖方支付上述“总值”的全部金额。卖方将在收到足额付款后安排生产及海关检验检疫手续（如适用）。 Within 3 business days after this Confirmation is accepted by the Buyer, the Buyer shall pay the Seller the full amount of the aforementioned Total Value via telegraphic transfer. The Seller will arrange for production, and Customs inspection and quarantine procedures (if applicable), after receipt of full payment. | D2: 自买方同意本确认书之日起3个工作日内，买方应以电汇方式向卖方支付上述“总值”的全部金额。卖方将在收到足额付款后安排生产及海关检验检疫手续（如适用）。 Trong vòng 03 ngày làm việc kể từ ngày Bên Mua chấp thuận Bản Xác nhận này, Bên Mua phải thanh toán toàn bộ số tiền của "Tổng giá trị" nói trên cho Bên Bán bằng hình thức chuyển khoản bằng điện (T/T). Bên Bán sẽ sắp xếp sản xuất và các thủ tục kiểm tra, kiểm dịch hải quan (nếu có) sau khi nhận được thanh toán đầy đủ.
A3: 先款后货RDC | B3: RDC仓库发运日 | C3: 自买方同意本确认书之日起3个工作日内，买方应以电汇方式向卖方支付上述“总值”的全部金额。卖方将在收到足额付款后的【X】个工作日内，安排从其在越南境内的RDC仓库发货。 Within 3 business days after this Confirmation is accepted by the Buyer, the Buyer shall pay the Seller the full amount of the aforementioned "Total Value" via telegraphic transfer (T/T). The Seller will arrange to dispatch the Products from its RDC warehouse in Vietnam within 【X】 business days upon receipt of the full payment. | D3: 自买方同意本确认书之日起3个工作日内，买方应以电汇方式向卖方支付上述“总值”的全部金额。卖方将在收到足额付款后的【X】个工作日内，安排从其在越南境内的RDC仓库发货。 Trong vòng 03 ngày làm việc kể từ ngày Bên Mua chấp thuận Bản Xác nhận này, Bên Mua phải thanh toán toàn bộ số tiền của "Tổng giá trị" nói trên cho Bên Bán bằng hình thức chuyển khoản bằng điện (T/T). Bên Bán sẽ sắp xếp xuất hàng từ kho RDC của mình tại Việt Nam trong vòng 【X】 ngày làm việc kể từ khi nhận được thanh toán đầy đủ.
B4: 送达约定到货地点 | C4: 订单生效之日起14个工作日内，乙方应支付订单金额的【100】%作为预付款；自产品到达越南目的港/站后3个工作日内，乙方应支付订单金额剩余的全部款项。甲方将在收到订单100%款项后送货到乙方指定的收货地点。 Within 14 business days after the effective date of the order, the Buyer shall pay 【100】% of the order amount as advance payment; within 3 business days after the Products arrive at the port/station of destination in Vietnam, the Buyer shall pay the remaining full amount of the order. The Seller will deliver the Products to the receiving location designated by the Buyer upon receipt of 100% of the order payment. | D4: 订单生效之日起14个工作日内，乙方应支付订单金额的【100】%作为预付款；自产品到达越南目的港/站后3个工作日内，乙方应支付订单金额剩余的全部款项。甲方将在收到订单100%款项后送货到乙方指定的收货地点。 Trong vòng 14 ngày làm việc kể từ ngày đơn hàng có hiệu lực, Bên Mua phải thanh toán 【100】% giá trị đơn hàng dưới hình thức tiền tạm ứng; trong vòng 03 ngày làm việc kể từ ngày sản phẩm đến cảng/ga đích tại Việt Nam, Bên Mua phải thanh toán toàn bộ số tiền còn lại của đơn hàng. Bên Bán sẽ giao hàng đến địa điểm nhận hàng do Bên Mua chỉ định sau khi nhận được 100% giá trị thanh toán của đơn hàng.
B5: 送达约定到货地点 | C5: 订单生效之日起3个工作日内，乙方应支付订单金额的【100】%作为预付款；自产品到达越南目的港/站后3个工作日内，乙方应支付订单金额剩余的全部款项。甲方将在收到订单100%款项后送货到乙方指定的收货地点。 Within 3 business days after the effective date of the order, the Buyer shall pay 【100】% of the order amount as advance payment; within 3 business days after the Products arrive at the port/station of destination in Vietnam, the Buyer shall pay the remaining full amount of the order. The Seller will deliver the Products to the receiving location designated by the Buyer upon receipt of 100% of the order payment. | D5: 订单生效之日起3个工作日内，乙方应支付订单金额的【100】%作为预付款；自产品到达越南目的港/站后3个工作日内，乙方应支付订单金额剩余的全部款项。甲方将在收到订单100%款项后送货到乙方指定的收货地点。 Trong vòng 03 ngày làm việc kể từ ngày đơn hàng có hiệu lực, Bên Mua phải thanh toán 【100】% giá trị đơn hàng dưới hình thức tiền tạm ứng; trong vòng 03 ngày làm việc kể từ ngày sản phẩm đến cảng/ga đích tại Việt Nam, Bên Mua phải thanh toán toàn bộ số tiền còn lại của đơn hàng. Bên Bán sẽ giao hàng đến địa điểm nhận hàng do Bên Mua chỉ định sau khi nhận được 100% giá trị thanh toán của đơn hàng.
A6: 赊销 | B6: 卖方工厂装货日后XX天 | C6: 自卖方发货之日起【X日】内，买方应以电汇方式向卖方支付上述“总值”的全部金额。 Within【x days】 after the date on which the Products are dispatched by the Seller, the Buyer shall pay the Seller the full amount of the aforementioned Total Value via telegraphic transfer. | D6: 自卖方发货之日起【X】日内，买方应以电汇方式向卖方支付上述“总值”的全部金额。 Trong vòng 【X】 ngày kể từ ngày Bên Bán giao hàng (phát hàng), Bên Mua phải thanh toán toàn bộ số tiền của "Tổng giá trị" nói trên cho Bên Bán bằng hình thức chuyển khoản bằng điện (T/T).
B7: 提单装船日后XX天 | C7: 自提单装船日起【X日】内，买方应以电汇方式向卖方支付上述“总值”的全部金额。 Within 【x days】 after the date on which the Products are laden on board the vessel in accordance with the Bill of Lading, the Buyer shall pay the Seller the full amount of the aforementioned Total Value via telegraphic transfer. | D7: 自提单装船日起【X】日内，买方应以电汇方式向卖方支付上述“总值”的全部金额。 Trong vòng 【X】 ngày kể từ ngày Sản phẩm được xếp lên tàu theo Vận đơn (Bill of Lading), Bên Mua phải thanh toán toàn bộ số tiền của "Tổng giá trị" nói trên cho Bên Bán bằng hình thức chuyển khoản bằng điện (T/T).
B8: RDC仓库发运日 | C8: 自卖方从其在越南境内的RDC仓库发货之日起【X日】内，买方应以电汇方式向卖方支付上述“总值”的全部金额。 Within 【x days】 from the date on which the Seller ships the Products from its RDC warehouse in Vietnam, the Buyer shall pay the Seller the full amount of the aforementioned Total Value via telegraphic transfer. | D8: 自卖方从其在越南境内的RDC仓库发货之日起【X】日内，买方应以电汇方式向卖方支付上述“总值”的全部金额。 Trong vòng 【X】 ngày kể từ ngày Bên Bán xuất hàng từ kho RDC của mình tại Việt Nam, Bên Mua phải thanh toán toàn bộ số tiền của "Tổng giá trị" nói trên cho Bên Bán bằng hình thức chuyển khoản bằng điện (T/T).
B9: 送达约定到货地点 | C9: 自卖方将产品送达至到货地点之日起【X日】内，买方应以电汇方式向卖方支付上述“总值”的全部金额。 Within 【x days】 from the date on which the Seller delivers the Products to the Delivery Location, the Buyer shall pay the Seller the full amount of the aforementioned Total Value via telegraphic transfer. | D9: 自卖方将产品送达至约定到货地点之日起【X】日内，买方应以电汇方式向卖方支付上述“总值”的全部金额。 Trong vòng 【X】 ngày kể từ ngày Bên Bán giao Sản phẩm đến Địa điểm giao hàng đã thỏa thuận, Bên Mua phải thanh toán toàn bộ số tiền của "Tổng giá trị" nói trên cho Bên Bán bằng hình thức chuyển khoản bằng điện (T/T).
B10: 送达约定到货地点 | C10: 订单生效之日起3个工作日内，乙方应支付订单金额的【30】%作为预付款；自产品到达越南目的港/站后3个工作日内，乙方应支付订单金额剩余的全部款项。甲方将在收到订单100%款项后送货到乙方指定的收货地点。 Within 3 business days after the effective date of the order, the Buyer shall pay 【30】% of the order amount as advance payment; within 3 business days after the Products arrive at the port/station of destination in Vietnam, the Buyer shall pay the remaining full amount of the order. The Seller will deliver the Products to the receiving location designated by the Buyer upon receipt of 100% of the order payment. | D10: 订单生效之日起3个工作日内，乙方应支付订单金额的【30】%作为预付款；自产品到达越南目的港/站后3个工作日内，乙方应支付订单金额剩余的全部款项。甲方将在收到订单100%款项后送货到乙方指定的收货地点。 Trong vòng 03 ngày làm việc kể từ ngày đơn hàng có hiệu lực, Bên Mua phải thanh toán 【30】% giá trị đơn hàng dưới hình thức tiền tạm ứng; trong vòng 03 ngày làm việc kể từ ngày sản phẩm đến cảng/ga đích tại Việt Nam, Bên Mua phải thanh toán toàn bộ số tiền còn lại của đơn hàng. Bên Bán sẽ giao hàng đến địa điểm nhận hàng do Bên Mua chỉ định sau khi nhận được 100% giá trị thanh toán của đơn hàng.
B11: 送达约定到货地点 | C11: 订单生效之日起3个工作日内，乙方应支付订单金额的【50】%作为预付款；自产品到达越南目的港/站后3个工作日内，乙方应支付订单金额剩余的全部款项。甲方将在收到订单100%款项后送货到乙方指定的收货地点。 Within 3 business days after the effective date of the order, the Buyer shall pay 【50】% of the order amount as advance payment; within 3 business days after the Products arrive at the port/station of destination in Vietnam, the Buyer shall pay the remaining full amount of the order. The Seller will deliver the Products to the receiving location designated by the Buyer upon receipt of 100% of the order payment. | D11: 订单生效之日起3个工作日内，乙方应支付订单金额的【50】%作为预付款；自产品到达越南目的港/站后3个工作日内，乙方应支付订单金额剩余的全部款项。甲方将在收到订单100%款项后送货到乙方指定的收货地点。 Trong vòng 03 ngày làm việc kể từ ngày đơn hàng có hiệu lực, Bên Mua phải thanh toán 【50】% giá trị đơn hàng dưới hình thức tiền tạm ứng; trong vòng 03 ngày làm việc kể từ ngày sản phẩm đến cảng/ga đích tại Việt Nam, Bên Mua phải thanh toán toàn bộ số tiền còn lại của đơn hàng. Bên Bán sẽ giao hàng đến địa điểm nhận hàng do Bên Mua chỉ định sau khi nhận được 100% giá trị thanh toán của đơn hàng.
B12: 实际以信用证要求为准 | C12: 买方应使用信用证向卖方支付上述“总值”的全部金额，详细约定见卖方同意的信用证内容以及双方就信用证另行签订的《补充协议》（具体名称以双方实际签订的协议为准）。 The Buyer shall pay the Seller the full amount of the aforementioned Total Value via letter of credit, in accordance with the content of the letter of credit agreed by the Seller and the Supplementary Agreement (the specific title of which shall be subject to the actual agreement concluded) separately entered into by the Parties regarding payment via letter of credit. | D12: 买方应使用信用证向卖方支付上述“总值”的全部金额，详细约定见卖方同意的信用证内容以及双方就信用证另行签订的《补充协议》（具体名称以双方实际签订的协议为准）。 Bên Mua phải thanh toán toàn bộ số tiền của "Tổng giá trị" nói trên cho Bên Bán bằng Thư tín dụng (L/C), chi tiết quy định theo nội dung L/C đã được Bên Bán chấp thuận và "Thỏa thuận bổ sung" (tên gọi cụ thể sẽ theo hợp đồng thực tế được ký kết giữa hai bên) được hai Bên ký kết riêng liên quan đến việc thanh toán bằng L/C.
C13: 不作为一级经销商合作。Not cooperating as a Tier 1 distributor. | D13: 不作为一级经销商合作。Không hợp tác với tư cách nhà phân phối cấp 1.
